Workbook

Sheet Overview
A1: QC overview – all subjects
A2: Everything on this sheet is a live formula over the Subjects sheet (counts, %, averages). Blue cell = the only typed input.
A4: 1. Coverage | B4: Value
A5: Expected subjects (sub-001 … sub-608) | B5: 608
A6: Subjects in file | B6: =COUNTA(Subjects!$A$2:$A$609) -> 608
A7: Missing subjects | B7: =B5-B6 -> 0
A8: Duplicate subject rows | B8: =B6-SUMPRODUCT(1/COUNTIF(Subjects!$A$2:$A$609,Subjects!$A$2:$A$609)) -> 0
A10: 2. Subject status | B10: Subjects | C10: % of all
A11: COMPLETED (analysed) | B11: =COUNTIF(Subjects!$B$2:$B$609,"COMPLETED") -> 427 | C11: =B11/$B$6 -> 0.70230263
A12: REJECTED (screened out, no QC) | B12: =COUNTIF(Subjects!$B$2:$B$609,"REJECTED") -> 181 | C12: =B12/$B$6 -> 0.29769737
A13: Total | B13: =B11+B12 -> 608 | C13: =B13/$B$6 -> 1
A15: 3. Why subjects were rejected | B15: Subjects | C15: % of rejected
A16: Age above 60 (any) | B16: =COUNTIFS(Subjects!$B$2:$B$609,"REJECTED",Subjects!$F$2:$F$609,"*Age above*") -> 94 | C16: =B16/$B$12 -> 0.51933702
A17: Late triggers (any) | B17: =COUNTIFS(Subjects!$B$2:$B$609,"REJECTED",Subjects!$F$2:$F$609,"*Late triggers*") -> 99 | C17: =B17/$B$12 -> 0.54696133
A18: Both reasons | B18: =COUNTIFS(Subjects!$B$2:$B$609,"REJECTED",Subjects!$F$2:$F$609,"*Age above*",Subjects!$F$2:$F$609,"*Late triggers*") -> 12 | C18: =B18/$B$12 -> 0.066298343
A19: Age only | B19: =B16-B18 -> 82 | C19: =B19/$B$12 -> 0.45303867
A20: Late triggers only | B20: =B17-B18 -> 87 | C20: =B20/$B$12 -> 0.48066298
A21: Total rejected (unique) | B21: =B19+B20+B18 -> 181 | C21: =B21/$B$12 -> 1
A23: 4. QC verdict of analysed subjects | B23: Subjects | C23: % of analysed
A24: PASS | B24: =COUNTIF(Subjects!$C$2:$C$609,"PASS") -> 6 | C24: =B24/$B$11 -> 0.014051522
A25: FLAG | B25: =COUNTIF(Subjects!$C$2:$C$609,"FLAG") -> 186 | C25: =B25/$B$11 -> 0.43559719
A26: FAIL | B26: =COUNTIF(Subjects!$C$2:$C$609,"FAIL") -> 235 | C26: =B26/$B$11 -> 0.55035129
A27: Total | B27: =SUM(B24:B26) -> 427 | C27: =B27/$B$11 -> 1
A29: 5. Subject usability label (analysed) | B29: Subjects | C29: % of analysed
A30: USABLE | B30: =COUNTIF(Subjects!$D$2:$D$609,"USABLE") -> 3 | C30: =B30/$B$11 -> 0.0070257611
A31: USABLE_WITH_FLAGS | B31: =COUNTIF(Subjects!$D$2:$D$609,"USABLE_WITH_FLAGS") -> 8 | C31: =B31/$B$11 -> 0.018735363
A32: USABLE_NEEDS_INTERPOLATION | B32: =COUNTIF(Subjects!$D$2:$D$609,"USABLE_NEEDS_INTERPOLATION") -> 181 | C32: =B32/$B$11 -> 0.42388759
A33: PARTIALLY_USABLE | B33: =COUNTIF(Subjects!$D$2:$D$609,"PARTIALLY_USABLE") -> 230 | C33: =B33/$B$11 -> 0.53864169
A34: REJECT | B34: =COUNTIF(Subjects!$D$2:$D$609,"REJECT") -> 5 | C34: =B34/$B$11 -> 0.011709602
A35: Total | B35: =SUM(B30:B34) -> 427 | C35: =B35/$B$11 -> 1
A37: 6. Recording level (analysed subjects) | B37: Recordings | C37: % of expected
A38: Recordings expected | B38: =SUM(Subjects!$K$2:$K$609) -> 2276 | C38: =B38/$B$38 -> 1
A39: PASS | B39: =SUM(Subjects!$L$2:$L$609) -> 530 | C39: =B39/$B$38 -> 0.23286467
A40: FLAG | B40: =SUM(Subjects!$M$2:$M$609) -> 1290 | C40: =B40/$B$38 -> 0.56678383
A41: FAIL | B41: =SUM(Subjects!$N$2:$N$609) -> 456 | C41: =B41/$B$38 -> 0.20035149
A42: MISSING | B42: =SUM(Subjects!$O$2:$O$609) -> 0 | C42: =B42/$B$38 -> 0
A43: Usable recordings | B43: =SUM(Subjects!$P$2:$P$609) -> 1820 | C43: =B43/$B$38 -> 0.79964851
A44: USABLE | B44: =SUM(Subjects!$Q$2:$Q$609) -> 261 | C44: =B44/$B$38 -> 0.11467487
A45: USABLE_WITH_FLAGS | B45: =SUM(Subjects!$R$2:$R$609) -> 305 | C45: =B45/$B$38 -> 0.13400703
A46: USABLE_NEEDS_INTERPOLATION | B46: =SUM(Subjects!$S$2:$S$609) -> 1254 | C46: =B46/$B$38 -> 0.55096661
...

Sheet Subjects
A1: subject | B1: status | C1: qc_verdict | D1: screening_label | E1: headline | F1: rejection_reasons | G1: sex | H1: age | I1: handedness | J1: sessions_analysed | K1: recordings_expected | L1: PASS | M1: FLAG | N1: FAIL | O1: MISSING | P1: usable_recordings | Q1: USABLE | R1: USABLE_WITH_FLAGS | S1: USABLE_NEEDS_INTERPOLATION | T1: REJECT | U1: bad_channels (count of recordings) | V1: critical_bad_channels | W1: reason_codes | X1: alpha_ratio_EC_EO_median | Y1: line50_db_median | Z1: duration_s | AA1: started | AB1: finished | AC1: data_deleted_after_qc | AD1: mb_freed | AE1: retry_needed | AF1: qc_logic_version | AG1: folder
A2: sub-001 | B2: COMPLETED | C2: FAIL | D2: PARTIALLY_USABLE | E2: overall FAIL; PARTIALLY_USABLE: 5/8 recordings usable; bad channels in 6 recording(s) (FC1, AF3, AF7); alpha blocking OK (median 2.4); notch filter suggested for 4/8 recordings | G2: F | H2: 60 | I2: right | J2: ses-1, ses-2 | K2: 8 | L2: 0 | M2: 5 | N2: 3 | O2: 0 | P2: 5 | Q2: 0 | R2: 2 | S2: 3 | T2: 3 | U2: FC1 x4, F3 x3, Fz x3, F4 x3, AF7 x3, AF3 x3, AF4 x3, AF8 x3, F5 x3, F1 x3, F2 x3, F6 x3, Fp1 x2, Fp2 x2, FC2 x2, Cz x1 | V2: Cz, Fz | W2: CRITICAL_CHANNEL_BAD; LINE_NOISE; TOO_MANY_BAD_CHANNELS; USABLE_NEEDS_INTERPOLATION; WEAK_ALPHA_BLOCKING | X2: 2.42 | Y2: 15.6 | Z2: 81.3 | AA2: 2026-10-21T14:03:40+00:00 | AB2: 2026-10-21T14:05:01+00:00 | AC2: yes | AD2: 193 | AE2: =FALSE() -> FALSE | AF2: screening-2.2 | AG2: qc_output/sub-001
A3: sub-002 | B3: REJECTED | E3: Rejected: Age above 60 (67) | F3: Age above 60 (67) | G3: M | H3: 67 | I3: right | Z3: 0 | AA3: 2026-10-21T14:13:02+00:00 | AB3: 2026-10-21T14:13:02+00:00 | AE3: =FALSE() -> FALSE | AF3: screening-2.2 | AG3: qc_output/sub-002
A4: sub-003 | B4: COMPLETED | C4: FAIL | D4: PARTIALLY_USABLE | E4: overall FAIL; PARTIALLY_USABLE: 2/4 recordings usable; bad channels in 3 recording(s) (AF3, AF4, F1); alpha blocking OK (median 7.8); notch filter suggested for 4/4 recordings | G4: F | H4: 44 | I4: right | J4: ses-1 | K4: 4 | L4: 2 | M4: 0 | N4: 2 | O4: 0 | P4: 2 | Q4: 1 | R4: 0 | S4: 1 | T4: 2 | U4: Fp1 x2, Fp2 x2, Fz x2, F4 x2, AF3 x2, AF4 x2, F1 x2, F2 x2, F6 x2, FC2 x1, FC6 x1, FC4 x1 | V4: Fz | W4: CRITICAL_CHANNEL_BAD; TOO_MANY_BAD_CHANNELS; USABLE_NEEDS_INTERPOLATION | X4: 7.78 | Y4: 16.3 | Z4: 41.3 | AA4: 2026-10-21T14:13:03+00:00 | AB4: 2026-10-21T14:13:44+00:00 | AC4: yes | AD4: 101 | AE4: =FALSE() -> FALSE | AF4: screening-2.2 | AG4: qc_output/sub-003
A5: sub-004 | B5: COMPLETED | C5: FLAG | D5: USABLE_NEEDS_INTERPOLATION | E5: overall FLAG; USABLE_NEEDS_INTERPOLATION: 4/4 recordings usable; bad channels in 2 recording(s) (FC4, FC6); alpha blocking OK (median 13.2); notch filter suggested for 1/4 recordings | G5: F | H5: 24 | I5: right | J5: ses-1 | K5: 4 | L5: 2 | M5: 2 | N5: 0 | O5: 0 | P5: 4 | Q5: 1 | R5: 1 | S5: 2 | T5: 0 | U5: FC6 x2, FC4 x2 | W5: LINE_NOISE; USABLE_NEEDS_INTERPOLATION; WEAK_ALPHA_BLOCKING | X5: 13.19 | Y5: 9.2 | Z5: 44 | AA5: 2026-10-21T14:09:31+00:00 | AB5: 2026-10-21T14:10:15+00:00 | AC5: yes | AD5: 102 | AE5: =FALSE() -> FALSE | AF5: screening-2.2 | AG5: qc_output/sub-004
A6: sub-005 | B6: REJECTED | E6: Rejected: Late triggers (late_ses1=0, late_ses2=5) | F6: Late triggers (late_ses1=0, late_ses2=5) | G6: F | H6: 48 | I6: right | Z6: 0 | AA6: 2026-10-21T14:13:44+00:00 | AB6: 2026-10-21T14:13:44+00:00 | AE6: =FALSE() -> FALSE | AF6: screening-2.2 | AG6: qc_output/sub-005
A7: sub-006 | B7: COMPLETED | C7: FLAG | D7: USABLE_NEEDS_INTERPOLATION | E7: overall FLAG; USABLE_NEEDS_INTERPOLATION: 4/4 recordings usable; bad channels in 4 recording(s) (F1, FC1, Fz); alpha blocking weak (flag only) (median 1.2); notch filter suggested for 4/4 recordings | G7: F | H7: 57 | I7: right | J7: ses-1 | K7: 4 | L7: 0 | M7: 4 | N7: 0 | O7: 0 | P7: 4 | Q7: 0 | R7: 0 | S7: 4 | T7: 0 | U7: Fz x2, F1 x2, FC1 x2, F4 x1, F2 x1, F6 x1, F8 x1, FC5 x1, FC3 x1, F7 x1, AF8 x1 | V7: Fz | W7: CRITICAL_CHANNEL_BAD; LINE_NOISE; USABLE_NEEDS_INTERPOLATION; WEAK_ALPHA_BLOCKING | X7: 1.25 | Y7: 20.1 | Z7: 45.3 | AA7: 2026-10-21T14:13:44+00:00 | AB7: 2026-10-21T14:14:29+00:00 | AC7: yes | AD7: 96 | AE7: =FALSE() -> FALSE | AF7: screening-2.2 | AG7: qc_output/sub-006
A8: sub-007 | B8: COMPLETED | C8: FLAG | D8: USABLE_NEEDS_INTERPOLATION | E8: overall FLAG; USABLE_NEEDS_INTERPOLATION: 4/4 recordings usable; bad channels in 1 recording(s) (F2, F6, Fz); alpha blocking OK (median 3.5); notch filter suggested for 3/4 recordings | G8: F | H8: 24 | I8: right | J8: ses-1 | K8: 4 | L8: 0 | M8: 4 | N8: 0 | O8: 0 | P8: 4 | Q8: 0 | R8: 3 | S8: 1 | T8: 0 | U8: Fz x1, F2 x1, F6 x1 | V8: Fz | W8: CRITICAL_CHANNEL_BAD; LINE_NOISE; NO_ALPHA_BLOCKING; USABLE_NEEDS_INTERPOLATION | X8: 3.48 | Y8: 19.6 | Z8: 41.1 | AA8: 2026-10-21T14:11:04+00:00 | AB8: 2026-10-21T14:11:45+00:00 | AC8: yes | AD8: 97 | AE8: =FALSE() -> FALSE | AF8: screening-2.2 | AG8: qc_output/sub-007
A9: sub-008 | B9: REJECTED | E9: Rejected: Late triggers (late_ses1=1901, late_ses2=n/a) | F9: Late triggers (late_ses1=1901, late_ses2=n/a) | G9: M | H9: 39 | I9: left | Z9: 0 | AA9: 2026-10-21T14:14:30+00:00 | AB9: 2026-10-21T14:14:30+00:00 | AE9: =FALSE() -> FALSE | AF9: screening-2.2 | AG9: qc_output/sub-008
A10: sub-009 | B10: REJECTED | E10: Rejected: Late triggers (late_ses1=2080, late_ses2=n/a) | F10: Late triggers (late_ses1=2080, late_ses2=n/a) | G10: F | H10: 37 | I10: right | Z10: 0 | AA10: 2026-10-21T14:14:30+00:00 | AB10: 2026-10-21T14:14:30+00:00 | AE10: =FALSE() -> FALSE | AF10: screening-2.2 | AG10: qc_output/sub-009
A11: sub-010 | B11: COMPLETED | C11: FLAG | D11: USABLE_NEEDS_INTERPOLATION | E11: overall FLAG; USABLE_NEEDS_INTERPOLATION: 4/4 recordings usable; bad channels in 4 recording(s) (F2, F1, F3); alpha blocking OK (median 3.1); notch filter suggested for 4/4 recordings | G11: F | H11: 23 | I11: right | J11: ses-1 | K11: 4 | L11: 0 | M11: 4 | N11: 0 | O11: 0 | P11: 4 | Q11: 0 | R11: 0 | S11: 4 | T11: 0 | U11: F1 x4, F2 x4, Fz x2, F3 x2, AF3 x1, AF4 x1 | V11: Fz | W11: CRITICAL_CHANNEL_BAD; LINE_NOISE; USABLE_NEEDS_INTERPOLATION | X11: 3.08 | Y11: 23.6 | Z11: 41.8 | AA11: 2026-10-21T14:14:30+00:00 | AB11: 2026-10-21T14:15:12+00:00 | AC11: yes | AD11: 96 | AE11: =FALSE() -> FALSE | AF11: screening-2.2 | AG11: qc_output/sub-010
A12: sub-011 | B12: COMPLETED | C12: FAIL | D12: PARTIALLY_USABLE | E12: overall FAIL; PARTIALLY_USABLE: 3/4 recordings usable; bad channels in 4 recording(s) (F5, Fz, FC2); alpha blocking OK (median 13.7); notch filter suggested for 4/4 recordings | G12: F | H12: 50 | I12: right | J12: ses-1 | K12: 4 | L12: 0 | M12: 3 | N12: 1 | O12: 0 | P12: 3 | Q12: 0 | R12: 0 | S12: 3 | T12: 1 | U12: F5 x3, Fz x2, FC2 x2, Cz x1, F1 x1 | V12: Cz, Fz | W12: CRITICAL_CHANNELS_BAD; CRITICAL_CHANNEL_BAD; LINE_NOISE; USABLE_NEEDS_INTERPOLATION | X12: 13.67 | Y12: 26 | Z12: 41.9 | AA12: 2026-10-21T14:15:12+00:00 | AB12: 2026-10-21T14:15:54+00:00 | AC12: yes | AD12: 96 | AE12: =FALSE() -> FALSE | AF12: screening-2.2 | AG12: qc_output/sub-011
A13: sub-012 | B13: COMPLETED | C13: FLAG | D13: USABLE_NEEDS_INTERPOLATION | E13: overall FLAG; USABLE_NEEDS_INTERPOLATION: 4/4 recordings usable; bad channels in 4 recording(s) (F1, Fz, F2); alpha blocking OK (median 4.0); notch filter suggested for 4/4 recordings | G13: M | H13: 33 | I13: right | J13: ses-1 | K13: 4 | L13: 0 | M13: 4 | N13: 0 | O13: 0 | P13: 4 | Q13: 0 | R13: 0 | S13: 4 | T13: 0 | U13: Fz x4, F1 x4, F2 x2 | V13: Fz | W13: CRITICAL_CHANNEL_BAD; LOW_ALPHA_PROMINENCE; NO_ALPHA_BLOCKING; USABLE_NEEDS_INTERPOLATION | X13: 4.01 | Y13: 18.2 | Z13: 41.5 | AA13: 2026-10-21T14:15:54+00:00 | AB13: 2026-10-21T14:16:36+00:00 | AC13: yes | AD13: 98 | AE13: =FALSE() -> FALSE | AF13: screening-2.2 | AG13: qc_output/sub-012
A14: sub-013 | B14: REJECTED | E14: Rejected: Late triggers (late_ses1=1364, late_ses2=n/a) | F14: Late triggers (late_ses1=1364, late_ses2=n/a) | G14: F | H14: 49 | I14: right | Z14: 0 | AA14: 2026-10-21T14:16:36+00:00 | AB14: 2026-10-21T14:16:36+00:00 | AE14: =FALSE() -> FALSE | AF14: screening-2.2 | AG14: qc_output/sub-013
A15: sub-014 | B15: REJECTED | E15: Rejected: Age above 60 (64) | F15: Age above 60 (64) | G15: M | H15: 64 | I15: right | Z15: 0 | AA15: 2026-10-21T14:16:36+00:00 | AB15: 2026-10-21T14:16:36+00:00 | AE15: =FALSE() -> FALSE | AF15: screening-2.2 | AG15: qc_output/sub-014
A16: sub-015 | B16: REJECTED | E16: Rejected: Age above 60 (61) | F16: Age above 60 (61) | G16: F | H16: 61 | I16: right | Z16: 0 | AA16: 2026-10-21T14:16:36+00:00 | AB16: 2026-10-21T14:16:36+00:00 | AE16: =FALSE() -> FALSE | AF16: screening-2.2 | AG16: qc_output/sub-015
A17: sub-016 | B17: COMPLETED | C17: FLAG | D17: USABLE_WITH_FLAGS | E17: overall FLAG; USABLE_WITH_FLAGS: 4/4 recordings usable; no bad channels; alpha blocking OK (median 6.6) | G17: M | H17: 32 | I17: right | J17: ses-1 | K17: 4 | L17: 3 | M17: 1 | N17: 0 | O17: 0 | P17: 4 | Q17: 3 | R17: 1 | S17: 0 | T17: 0 | W17: LOW_ALPHA_PROMINENCE | X17: 6.58 | Y17: 6.7 | Z17: 42.5 | AA17: 2026-10-21T14:16:37+00:00 | AB17: 2026-10-21T14:17:20+00:00 | AC17: yes | AD17: 101 | AE17: =FALSE() -> FALSE | AF17: screening-2.2 | AG17: qc_output/sub-016
A18: sub-017 | B18: COMPLETED | C18: FAIL | D18: PARTIALLY_USABLE | E18: overall FAIL; PARTIALLY_USABLE: 2/4 recordings usable; bad channels in 4 recording(s) (AF3, AF4, F1); alpha blocking OK (median 5.2); notch filter suggested for 4/4 recordings | G18: M | H18: 50 | I18: right | J18: ses-1 | K18: 4 | L18: 0 | M18: 2 | N18: 2 | O18: 0 | P18: 2 | Q18: 0 | R18: 0 | S18: 2 | T18: 2 | U18: Fp1 x2, Fp2 x2, Fz x2, AF3 x2, AF4 x2, F1 x2, F2 x2, F8 x2, F3 x1, AF7 x1, AF8 x1, F4 x1, F7 x1 | V18: Fz | W18: CRITICAL_CHANNEL_BAD; LINE_NOISE; LOW_ALPHA_PROMINENCE; TOO_MANY_BAD_CHANNELS; USABLE_NEEDS_INTERPOLATION | X18: 5.2 | Y18: 24.7 | Z18: 40.5 | AA18: 2026-10-21T14:17:20+00:00 | AB18: 2026-10-21T14:18:00+00:00 | AC18: yes | AD18: 95 | AE18: =FALSE() -> FALSE | AF18: screening-2.2 | AG18: qc_output/sub-017
A19: sub-018 | B19: COMPLETED | C19: FAIL | D19: PARTIALLY_USABLE | E19: overall FAIL; PARTIALLY_USABLE: 2/4 recordings usable; bad channels in 2 recording(s) (AF3, AF4, AF7); alpha blocking weak (flag only) (median 1.3); notch filter suggested for 4/4 recordings | G19: F | H19: 20 | I19: right | J19: ses-1 | K19: 4 | L19: 1 | M19: 1 | N19: 2 | O19: 0 | P19: 2 | Q19: 1 | R19: 1 | S19: 0 | T19: 2 | U19: Fp1 x2, Fp2 x2, F3 x2, F4 x2, AF7 x2, AF3 x2, AF4 x2, AF8 x2, F1 x2, F2 x2, Fz x1, F5 x1 | V19: Fz | W19: CRITICAL_CHANNEL_BAD; LOW_ALPHA_PROMINENCE; TOO_MANY_BAD_CHANNELS; WEAK_ALPHA_BLOCKING | X19: 1.33 | Y19: 12.1 | Z19: 41.1 | AA19: 2026-10-21T14:18:01+00:00 | AB19: 2026-10-21T14:18:42+00:00 | AC19: yes | AD19: 97 | AE19: =FALSE() -> FALSE | AF19: screening-2.2 | AG19: qc_output/sub-018
A20: sub-019 | B20: COMPLETED | C20: FAIL | D20: PARTIALLY_USABLE | E20: overall FAIL; PARTIALLY_USABLE: 3/4 recordings usable; bad channels in 4 recording(s) (C6, FC4, FC6); alpha blocking weak (flag only) (median 0.8) | G20: F | H20: 42 | I20: left | J20: ses-1 | K20: 4 | L20: 0 | M20: 3 | N20: 1 | O20: 0 | P20: 3 | Q20: 0 | R20: 0 | S20: 3 | T20: 1 | U20: FC6 x3, FC4 x3, C6 x3, Fz x2, F4 x2, FC2 x2, T8 x2, F2 x2, C4 x1, FT8 x1, AF4 x1, F1 x1 | V20: Fz | W20: CRITICAL_CHANNEL_BAD; LOW_ALPHA_PROMINENCE; NO_ALPHA_BLOCKING; TOO_MANY_BAD_CHANNELS; USABLE_NEEDS_INTERPOLATION | X20: 0.78 | Y20: 7.5 | Z20: 42.3 | AA20: 2026-10-21T14:18:42+00:00 | AB20: 2026-10-21T14:19:24+00:00 | AC20: yes | AD20: 98 | AE20: =FALSE() -> FALSE | AF20: screening-2.2 | AG20: qc_output/sub-019
A21: sub-020 | B21: REJECTED | E21: Rejected: Age above 60 (68) | F21: Age above 60 (68) | G21: M | H21: 68 | I21: right | Z21: 0 | AA21: 2026-10-21T14:19:25+00:00 | AB21: 2026-10-21T14:19:25+00:00 | AE21: =FALSE() -> FALSE | AF21: screening-2.2 | AG21: qc_output/sub-020
A22: sub-021 | B22: COMPLETED | C22: FLAG | D22: USABLE_NEEDS_INTERPOLATION | E22: overall FLAG; USABLE_NEEDS_INTERPOLATION: 4/4 recordings usable; bad channels in 3 recording(s) (F8, F4, F6); alpha blocking weak (flag only) (median 1.4); notch filter suggested for 3/4 recordings | G22: F | H22: 23 | I22: left | J22: ses-1 | K22: 4 | L22: 2 | M22: 2 | N22: 0 | O22: 0 | P22: 4 | Q22: 1 | R22: 0 | S22: 3 | T22: 0 | U22: F8 x2, P4 x1, F7 x1, FC1 x1, FC2 x1, F4 x1, F5 x1, F6 x1 | W22: LINE_NOISE; USABLE_NEEDS_INTERPOLATION; WEAK_ALPHA_BLOCKING | X22: 1.4 | Y22: 15.5 | Z22: 42.4 | AA22: 2026-10-21T14:19:25+00:00 | AB22: 2026-10-21T14:20:07+00:00 | AC22: yes | AD22: 100 | AE22: =FALSE() -> FALSE | AF22: screening-2.2 | AG22: qc_output/sub-021
A23: sub-022 | B23: COMPLETED | C23: FAIL | D23: PARTIALLY_USABLE | E23: overall FAIL; PARTIALLY_USABLE: 2/4 recordings usable; bad channels in 4 recording(s) (F1, F2, AF3); alpha blocking OK (median 2.9); notch filter suggested for 2/4 recordings | G23: M | H23: 60 | I23: right | J23: ses-1 | K23: 4 | L23: 0 | M23: 2 | N23: 2 | O23: 0 | P23: 2 | Q23: 0 | R23: 0 | S23: 2 | T23: 2 | U23: F1 x4, F2 x4, F4 x3, AF3 x3, AF4 x3, Fz x2, F3 x2, FC1 x2, Fp1 x1, Fp2 x1, FC2 x1 | V23: Fz | W23: CRITICAL_CHANNEL_BAD; TOO_MANY_BAD_CHANNELS; USABLE_NEEDS_INTERPOLATION | X23: 2.88 | Y23: 11.7 | Z23: 42 | AA23: 2026-10-21T14:20:08+00:00 | AB23: 2026-10-21T14:20:49+00:00 | AC23: yes | AD23: 95 | AE23: =FALSE() -> FALSE | AF23: screening-2.2 | AG23: qc_output/sub-022
A24: sub-023 | B24: COMPLETED | C24: FAIL | D24: PARTIALLY_USABLE | E24: overall FAIL; PARTIALLY_USABLE: 3/4 recordings usable; bad channels in 4 recording(s) (F2, FC2, Fz); alpha blocking OK (median 3.7); notch filter suggested for 4/4 recordings | G24: F | H24: 31 | I24: right | J24: ses-1 | K24: 4 | L24: 0 | M24: 3 | N24: 1 | O24: 0 | P24: 3 | Q24: 0 | R24: 0 | S24: 3 | T24: 1 | U24: Fz x2, F2 x2, FC2 x2, F8 x1, FC1 x1, FC3 x1, F7 x1, F3 x1, F4 x1, AF7 x1, AF8 x1, F5 x1, F6 x1 | V24: Fz | W24: CRITICAL_CHANNEL_BAD; HIGH_LINE_NOISE; TOO_MANY_BAD_CHANNELS; USABLE_NEEDS_INTERPOLATION | X24: 3.73 | Y24: 25.6 | Z24: 40.8 | AA24: 2026-10-21T14:20:50+00:00 | AB24: 2026-10-21T14:21:31+00:00 | AC24: yes | AD24: 97 | AE24: =FALSE() -> FALSE | AF24: screening-2.2 | AG24: qc_output/sub-023
A25: sub-024 | B25: COMPLETED | C25: FAIL | D25: PARTIALLY_USABLE | E25: overall FAIL; PARTIALLY_USABLE: 2/4 recordings usable; bad channels in 4 recording(s) (FC2, AF3, AF4); alpha blocking OK (median 4.0); notch filter suggested for 4/4 recordings | G25: F | H25: 47 | I25: right | J25: ses-1 | K25: 4 | L25: 2 | M25: 0 | N25: 2 | O25: 0 | P25: 2 | Q25: 0 | R25: 0 | S25: 2 | T25: 2 | U25: FC2 x4, Fp1 x2, Fp2 x2, F3 x2, Fz x2, F4 x2, AF7 x2, AF3 x2, AF4 x2, AF8 x2, F1 x2, F2 x2, FC1 x2, F8 x1, F6 x1, FC3 x1, FC4 x1 | V25: Fz | W25: CRITICAL_CHANNEL_BAD; TOO_MANY_BAD_CHANNELS; USABLE_NEEDS_INTERPOLATION | X25: 4 | Y25: 13.4 | Z25: 40.6 | AA25: 2026-10-21T14:21:31+00:00 | AB25: 2026-10-21T14:22:11+00:00 | AC25: yes | AD25: 95 | AE25: =FALSE() -> FALSE | AF25: screening-2.2 | AG25: qc_output/sub-024
A26: sub-025 | B26: COMPLETED | C26: FLAG | D26: USABLE_WITH_FLAGS | E26: overall FLAG; USABLE_WITH_FLAGS: 4/4 recordings usable; no bad channels; alpha blocking OK (median 4.2); notch filter suggested for 4/4 recordings | G26: F | H26: 26 | I26: left | J26: ses-1 | K26: 4 | L26: 0 | M26: 4 | N26: 0 | O26: 0 | P26: 4 | Q26: 0 | R26: 4 | S26: 0 | T26: 0 | W26: LINE_NOISE | X26: 4.19 | Y26: 25.3 | Z26: 42.7 | AA26: 2026-10-21T14:22:12+00:00 | AB26: 2026-10-21T14:22:55+00:00 | AC26: yes | AD26: 101 | AE26: =FALSE() -> FALSE | AF26: screening-2.2 | AG26: qc_output/sub-025
A27: sub-026 | B27: COMPLETED | C27: FLAG | D27: USABLE_NEEDS_INTERPOLATION | E27: overall FLAG; USABLE_NEEDS_INTERPOLATION: 4/4 recordings usable; bad channels in 2 recording(s) (F1, FC2, Fp1); alpha blocking OK (median 8.3); notch filter suggested for 2/4 recordings | G27: F | H27: 59 | I27: right | J27: ses-1 | K27: 4 | L27: 3 | M27: 1 | N27: 0 | O27: 0 | P27: 4 | Q27: 2 | R27: 0 | S27: 2 | T27: 0 | U27: Fp1 x1, Fz x1, F1 x1, FC2 x1 | V27: Fz | W27: CRITICAL_CHANNEL_BAD; USABLE_NEEDS_INTERPOLATION | X27: 8.29 | Y27: 12 | Z27: 41.7 | AA27: 2026-10-21T14:22:55+00:00 | AB27: 2026-10-21T14:23:37+00:00 | AC27: yes | AD27: 97 | AE27: =FALSE() -> FALSE | AF27: screening-2.2 | AG27: qc_output/sub-026
A28: sub-027 | B28: REJECTED | E28: Rejected: Late triggers (late_ses1=15, late_ses2=n/a) | F28: Late triggers (late_ses1=15, late_ses2=n/a) | G28: F | H28: 51 | I28: right | Z28: 0 | AA28: 2026-10-21T14:23:37+00:00 | AB28: 2026-10-21T14:23:37+00:00 | AE28: =FALSE() -> FALSE | AF28: screening-2.2 | AG28: qc_output/sub-027
A29: sub-028 | B29: COMPLETED | C29: FLAG | D29: USABLE_NEEDS_INTERPOLATION | E29: overall FLAG; USABLE_NEEDS_INTERPOLATION: 8/8 recordings usable; bad channels in 6 recording(s) (F5, F6, F4); alpha blocking OK (median 4.5); notch filter suggested for 4/8 recordings | G29: M | H29: 48 | I29: right | J29: ses-1, ses-2 | K29: 8 | L29: 2 | M29: 6 | N29: 0 | O29: 0 | P29: 8 | Q29: 0 | R29: 2 | S29: 6 | T29: 0 | U29: F5 x4, F6 x4, F7 x2, F3 x2, F4 x2, Fz x2, AF8 x1, FC2 x1 | V29: Fz | W29: CRITICAL_CHANNEL_BAD; LINE_NOISE; LOW_ALPHA_PROMINENCE; NO_ALPHA_BLOCKING; USABLE_NEEDS_INTERPOLATION | X29: 4.5 | Y29: 12.2 | Z29: 82.9 | AA29: 2026-10-21T14:23:37+00:00 | AB29: 2026-10-21T14:25:00+00:00 | AC29: yes | AD29: 196 | AE29: =FALSE() -> FALSE | AF29: screening-2.2 | AG29: qc_output/sub-028
A30: sub-029 | B30: COMPLETED | C30: FAIL | D30: PARTIALLY_USABLE | E30: overall FAIL; PARTIALLY_USABLE: 3/4 recordings usable; bad channels in 4 recording(s) (AF3, AF4, F1); alpha blocking weak (flag only) (median 1.2); notch filter suggested for 4/4 recordings | G30: F | H30: 36 | I30: right | J30: ses-1 | K30: 4 | L30: 1 | M30: 2 | N30: 1 | O30: 0 | P30: 3 | Q30: 0 | R30: 0 | S30: 3 | T30: 1 | U30: Fp1 x2, Fz x2, AF3 x2, AF4 x2, F1 x2, F2 x2, F6 x2, Fp2 x1, F3 x1, F4 x1, AF7 x1, AF8 x1, F5 x1, FC1 x1, FC3 x1 | V30: Fz | W30: CRITICAL_CHANNEL_BAD; LINE_NOISE; NO_ALPHA_BLOCKING; TOO_MANY_BAD_CHANNELS; USABLE_NEEDS_INTERPOLATION | X30: 1.17 | Y30: 16.4 | Z30: 42.2 | AA30: 2026-10-21T14:25:01+00:00 | AB30: 2026-10-21T14:25:43+00:00 | AC30: yes | AD30: 95 | AE30: =FALSE() -> FALSE | AF30: screening-2.2 | AG30: qc_output/sub-029
A31: sub-030 | B31: REJECTED | E31: Rejected: Age above 60 (62) | F31: Age above 60 (62) | G31: F | H31: 62 | I31: right | Z31: 0 | AA31: 2026-10-21T14:25:43+00:00 | AB31: 2026-10-21T14:25:43+00:00 | AE31: =FALSE() -> FALSE | AF31: screening-2.2 | AG31: qc_output/sub-030
A32: sub-031 | B32: COMPLETED | C32: FAIL | D32: PARTIALLY_USABLE | E32: overall FAIL; PARTIALLY_USABLE: 2/4 recordings usable; bad channels in 4 recording(s) (F2, Fz, F1); alpha blocking OK (median 6.5); notch filter suggested for 3/4 recordings | G32: F | H32: 26 | I32: right | J32: ses-1 | K32: 4 | L32: 0 | M32: 2 | N32: 2 | O32: 0 | P32: 2 | Q32: 0 | R32: 0 | S32: 2 | T32: 2 | U32: Fz x3, F2 x3, F1 x3, F4 x2, AF7 x2, AF3 x2, AF4 x2, AF8 x2, Fp1 x1, Fp2 x1, F3 x1, F5 x1 | V32: Fz | W32: CRITICAL_CHANNEL_BAD; LINE_NOISE; TOO_MANY_BAD_CHANNELS; USABLE_NEEDS_INTERPOLATION | X32: 6.49 | Y32: 16.4 | Z32: 41.1 | AA32: 2026-10-21T14:25:44+00:00 | AB32: 2026-10-21T14:26:25+00:00 | AC32: yes | AD32: 95 | AE32: =FALSE() -> FALSE | AF32: screening-2.2 | AG32: qc_output/sub-031
A33: sub-032 | B33: COMPLETED | C33: FAIL | D33: PARTIALLY_USABLE | E33: overall FAIL; PARTIALLY_USABLE: 2/4 recordings usable; bad channels in 4 recording(s) (F2, Fz, F1); alpha blocking OK (median 3.2); notch filter suggested for 2/4 recordings | G33: F | H33: 20 | I33: right | J33: ses-1 | K33: 4 | L33: 0 | M33: 2 | N33: 2 | O33: 0 | P33: 2 | Q33: 0 | R33: 0 | S33: 2 | T33: 2 | U33: F2 x4, Fz x3, F1 x3, F3 x2, F4 x2, AF7 x2, AF3 x2, AF8 x2, Fp1 x1, Fp2 x1, AF4 x1, F5 x1, F6 x1 | V33: Fz | W33: CRITICAL_CHANNEL_BAD; LINE_NOISE; LOW_ALPHA_PROMINENCE; TOO_MANY_BAD_CHANNELS; USABLE_NEEDS_INTERPOLATION | X33: 3.21 | Y33: 14.7 | Z33: 41.2 | AA33: 2026-10-21T14:26:26+00:00 | AB33: 2026-10-21T14:27:07+00:00 | AC33: yes | AD33: 96 | AE33: =FALSE() -> FALSE | AF33: screening-2.2 | AG33: qc_output/sub-032
A34: sub-033 | B34: COMPLETED | C34: FLAG | D34: USABLE_NEEDS_INTERPOLATION | E34: overall FLAG; USABLE_NEEDS_INTERPOLATION: 8/8 recordings usable; bad channels in 6 recording(s) (Fz, F5, F4); alpha blocking OK (median 7.5); notch filter suggested for 6/8 recordings | G34: M | H34: 32 | I34: right | J34: ses-1, ses-2 | K34: 8 | L34: 4 | M34: 4 | N34: 0 | O34: 0 | P34: 8 | Q34: 2 | R34: 0 | S34: 6 | T34: 0 | U34: Fz x4, F5 x2, F4 x1, F2 x1, F7 x1, F8 x1 | V34: Fz | W34: CRITICAL_CHANNEL_BAD; USABLE_NEEDS_INTERPOLATION | X34: 7.52 | Y34: 13.1 | Z34: 75.1 | AA34: 2026-10-21T14:27:08+00:00 | AB34: 2026-10-21T14:28:23+00:00 | AC34: yes | AD34: 191 | AE34: =FALSE() -> FALSE | AF34: screening-2.2 | AG34: qc_output/sub-033
A35: sub-034 | B35: COMPLETED | C35: FAIL | D35: PARTIALLY_USABLE | E35: overall FAIL; PARTIALLY_USABLE: 3/4 recordings usable; bad channels in 3 recording(s) (Fz, F2, AF4); alpha blocking OK (median 3.3); notch filter suggested for 4/4 recordings | G35: M | H35: 41 | I35: right | J35: ses-1 | K35: 4 | L35: 2 | M35: 1 | N35: 1 | O35: 0 | P35: 3 | Q35: 1 | R35: 0 | S35: 2 | T35: 1 | U35: Fz x2, F2 x2, Fp1 x1, Fp2 x1, AF7 x1, AF3 x1, AF4 x1, AF8 x1, F1 x1, F6 x1 | V35: Fz | W35: CRITICAL_CHANNEL_BAD; TOO_MANY_BAD_CHANNELS; USABLE_NEEDS_INTERPOLATION | X35: 3.32 | Y35: 13.4 | Z35: 41.1 | AA35: 2026-10-21T14:28:24+00:00 | AB35: 2026-10-21T14:29:05+00:00 | AC35: yes | AD35: 96 | AE35: =FALSE() -> FALSE | AF35: screening-2.2 | AG35: qc_output/sub-034
A36: sub-035 | B36: COMPLETED | C36: FLAG | D36: USABLE_NEEDS_INTERPOLATION | E36: overall FLAG; USABLE_NEEDS_INTERPOLATION: 4/4 recordings usable; bad channels in 3 recording(s) (F8, FC1, FC3); alpha blocking OK (median 3.7); notch filter suggested for 2/4 recordings | G36: M | H36: 36 | I36: right | J36: ses-1 | K36: 4 | L36: 3 | M36: 1 | N36: 0 | O36: 0 | P36: 4 | Q36: 1 | R36: 0 | S36: 3 | T36: 0 | U36: FC1 x2, F8 x2, FC5 x2, FC3 x2, Fz x1, F1 x1, FC2 x1 | V36: Fz | W36: CRITICAL_CHANNEL_BAD; USABLE_NEEDS_INTERPOLATION | X36: 3.73 | Y36: 9.8 | Z36: 40.8 | AA36: 2026-10-21T14:29:05+00:00 | AB36: 2026-10-21T14:29:46+00:00 | AC36: yes | AD36: 96 | AE36: =FALSE() -> FALSE | AF36: screening-2.2 | AG36: qc_output/sub-035
A37: sub-036 | B37: COMPLETED | C37: FAIL | D37: PARTIALLY_USABLE | E37: overall FAIL; PARTIALLY_USABLE: 3/4 recordings usable; bad channels in 4 recording(s) (F2, F1, Fz); alpha blocking OK (median 4.5); notch filter suggested for 1/4 recordings | G37: F | H37: 53 | I37: left | J37: ses-1 | K37: 4 | L37: 0 | M37: 3 | N37: 1 | O37: 0 | P37: 3 | Q37: 0 | R37: 0 | S37: 3 | T37: 1 | U37: F1 x4, F2 x4, Fz x3, F4 x2, FC2 x1, Fp1 x1, Fp2 x1, F7 x1, F3 x1, F8 x1, AF7 x1, AF3 x1, AF4 x1, AF8 x1, F5 x1, F6 x1 | V37: Fz | W37: CRITICAL_CHANNEL_BAD; LOW_ALPHA_PROMINENCE; TOO_MANY_BAD_CHANNELS; USABLE_NEEDS_INTERPOLATION | X37: 4.54 | Y37: 6.9 | Z37: 40.8 | AA37: 2026-10-21T14:29:47+00:00 | AB37: 2026-10-21T14:30:28+00:00 | AC37: yes | AD37: 95 | AE37: =FALSE() -> FALSE | AF37: screening-2.2 | AG37: qc_output/sub-036
A38: sub-037 | B38: REJECTED | E38: Rejected: Late triggers (late_ses1=445, late_ses2=n/a) | F38: Late triggers (late_ses1=445, late_ses2=n/a) | G38: M | H38: 30 | I38: right | Z38: 0 | AA38: 2026-10-21T14:30:28+00:00 | AB38: 2026-10-21T14:30:28+00:00 | AE38: =FALSE() -> FALSE | AF38: screening-2.2 | AG38: qc_output/sub-037
A39: sub-038 | B39: COMPLETED | C39: FLAG | D39: USABLE_NEEDS_INTERPOLATION | E39: overall FLAG; USABLE_NEEDS_INTERPOLATION: 8/8 recordings usable; bad channels in 4 recording(s) (FC2, F7, FC4); alpha blocking weak (flag only) (median 1.4); notch filter suggested for 3/8 recordings | G39: M | H39: 49 | I39: right | J39: ses-1, ses-2 | K39: 8 | L39: 1 | M39: 7 | N39: 0 | O39: 0 | P39: 8 | Q39: 0 | R39: 4 | S39: 4 | T39: 0 | U39: FC2 x3, F7 x2, FC4 x2, FC1 x1, F8 x1, Fz x1 | V39: Fz | W39: CRITICAL_CHANNEL_BAD; LOW_ALPHA_PROMINENCE; USABLE_NEEDS_INTERPOLATION; WEAK_ALPHA_BLOCKING | X39: 1.42 | Y39: 8.5 | Z39: 73.1 | AA39: 2026-10-21T14:30:28+00:00 | AB39: 2026-10-21T14:31:42+00:00 | AC39: yes | AD39: 192 | AE39: =FALSE() -> FALSE | AF39: screening-2.2 | AG39: qc_output/sub-038
A40: sub-039 | B40: COMPLETED | C40: FAIL | D40: PARTIALLY_USABLE | E40: overall FAIL; PARTIALLY_USABLE: 2/4 recordings usable; bad channels in 4 recording(s) (AF3, Fz, FC3); alpha blocking weak (flag only) (median 0.6); notch filter suggested for 4/4 recordings | G40: M | H40: 55 | I40: right | J40: ses-1 | K40: 4 | L40: 0 | M40: 2 | N40: 2 | O40: 0 | P40: 2 | Q40: 0 | R40: 0 | S40: 2 | T40: 2 | U40: Fz x3, AF3 x3, FC3 x3, Fp2 x2, F3 x2, AF7 x2, AF4 x2, AF8 x2, F5 x2, F1 x2, F2 x2, FC1 x2, Cz x1, Fp1 x1, F4 x1, FC5 x1, FT7 x1 | V40: Cz, Fz | W40: CRITICAL_CHANNELS_BAD; CRITICAL_CHANNEL_BAD; NO_ALPHA_BLOCKING; TOO_MANY_BAD_CHANNELS; USABLE_NEEDS_INTERPOLATION; WEAK_ALPHA_BLOCKING | X40: 0.58 | Y40: 17.1 | Z40: 41.1 | AA40: 2026-10-21T14:31:42+00:00 | AB40: 2026-10-21T14:32:23+00:00 | AC40: yes | AD40: 101 | AE40: =FALSE() -> FALSE | AF40: screening-2.2 | AG40: qc_output/sub-039
...

Sheet Recording_Ranking
A1: Rank | B1: Quality score (0-100) | C1: Subject | D1: Session | E1: Task | F1: Acq | G1: Label | H1: Overall | I1: Bad channels (n) | J1: Critical bad (n) | K1: Uncorrelated (n) | L1: Spatial corr | M1: 50 Hz noise (dB) | N1: Frozen (s) | O1: Duration (s) | P1: Alpha prominence (dB) | Q1: Bad channel names | R1: QC codes | T1: Score component | U1: Weight | V1: Best value (full score) | W1: Worst value (zero score)
A2: =IF(G2="REJECT",COUNTIF($G$2:$G$2277,"<>REJECT")+1+COUNTIFS($G$2:$G$2277,"REJECT",$B$2:$B$2277,">"&B2),1+COUNTIFS($G$2:$G$2277,"<>REJECT",$B$2:$B$2277,">"&B2)) -> 1 | B2: =ROUND(($U$2*MAX(0,MIN(1,($W$2-I2)/($W$2-$V$2)))+$U$3*MAX(0,MIN(1,($W$3-J2)/($W$3-$V$3)))+$U$4*MAX(0,MIN(1,($W$4-K2)/($W$4-$V$4)))+$U$5*MAX(0,MIN(1,($W$5-L2)/($W$5-$V$5)))+$U$6*MAX(0,MIN(1,($W$6-M2)/($W$6-$V$6)))+$U$7*MAX(0,MIN(1,($W$7-N2)/($W$7-$V$7)))+$U$8*IF(AND(O2>=$V$8,O2<=$W$8),1,0))/$U$9*100,2) -> 99.32 | C2: sub-584 | D2: ses-1 | E2: EyesOpen | F2: post | G2: USABLE_WITH_FLAGS | H2: FLAG | I2: 0 | J2: 0 | K2: 0 | L2: 0.85 | M2: 2.5 | N2: 0.16 | O2: 183 | P2: -3.04 | R2: NO_ALPHA_BLOCKING | T2: Bad channels (count) | U2: 35 | V2: 0 | W2: 8
A3: =IF(G3="REJECT",COUNTIF($G$2:$G$2277,"<>REJECT")+1+COUNTIFS($G$2:$G$2277,"REJECT",$B$2:$B$2277,">"&B3),1+COUNTIFS($G$2:$G$2277,"<>REJECT",$B$2:$B$2277,">"&B3)) -> 2 | B3: =ROUND(($U$2*MAX(0,MIN(1,($W$2-I3)/($W$2-$V$2)))+$U$3*MAX(0,MIN(1,($W$3-J3)/($W$3-$V$3)))+$U$4*MAX(0,MIN(1,($W$4-K3)/($W$4-$V$4)))+$U$5*MAX(0,MIN(1,($W$5-L3)/($W$5-$V$5)))+$U$6*MAX(0,MIN(1,($W$6-M3)/($W$6-$V$6)))+$U$7*MAX(0,MIN(1,($W$7-N3)/($W$7-$V$7)))+$U$8*IF(AND(O3>=$V$8,O3<=$W$8),1,0))/$U$9*100,2) -> 99.1 | C3: sub-584 | D3: ses-1 | E3: EyesClosed | F3: post | G3: USABLE_WITH_FLAGS | H3: FLAG | I3: 0 | J3: 0 | K3: 0 | L3: 0.8 | M3: 5.39 | N3: 0 | O3: 183 | P3: -0.44 | R3: LOW_ALPHA_PROMINENCE; NO_ALPHA_BLOCKING | T3: Critical channels bad (count: Fz Cz Pz O1 O2) | U3: 20 | V3: 0 | W3: 2
A4: =IF(G4="REJECT",COUNTIF($G$2:$G$2277,"<>REJECT")+1+COUNTIFS($G$2:$G$2277,"REJECT",$B$2:$B$2277,">"&B4),1+COUNTIFS($G$2:$G$2277,"<>REJECT",$B$2:$B$2277,">"&B4)) -> 3 | B4: =ROUND(($U$2*MAX(0,MIN(1,($W$2-I4)/($W$2-$V$2)))+$U$3*MAX(0,MIN(1,($W$3-J4)/($W$3-$V$3)))+$U$4*MAX(0,MIN(1,($W$4-K4)/($W$4-$V$4)))+$U$5*MAX(0,MIN(1,($W$5-L4)/($W$5-$V$5)))+$U$6*MAX(0,MIN(1,($W$6-M4)/($W$6-$V$6)))+$U$7*MAX(0,MIN(1,($W$7-N4)/($W$7-$V$7)))+$U$8*IF(AND(O4>=$V$8,O4<=$W$8),1,0))/$U$9*100,2) -> 98.82 | C4: sub-585 | D4: ses-1 | E4: EyesOpen | F4: post | G4: USABLE | H4: PASS | I4: 0 | J4: 0 | K4: 0 | L4: 0.81 | M4: 5.08 | N4: 0.2 | O4: 185 | P4: 0.83 | T4: Uncorrelated / noisy channels (count) | U4: 15 | V4: 0 | W4: 8
A5: =IF(G5="REJECT",COUNTIF($G$2:$G$2277,"<>REJECT")+1+COUNTIFS($G$2:$G$2277,"REJECT",$B$2:$B$2277,">"&B5),1+COUNTIFS($G$2:$G$2277,"<>REJECT",$B$2:$B$2277,">"&B5)) -> 4 | B5: =ROUND(($U$2*MAX(0,MIN(1,($W$2-I5)/($W$2-$V$2)))+$U$3*MAX(0,MIN(1,($W$3-J5)/($W$3-$V$3)))+$U$4*MAX(0,MIN(1,($W$4-K5)/($W$4-$V$4)))+$U$5*MAX(0,MIN(1,($W$5-L5)/($W$5-$V$5)))+$U$6*MAX(0,MIN(1,($W$6-M5)/($W$6-$V$6)))+$U$7*MAX(0,MIN(1,($W$7-N5)/($W$7-$V$7)))+$U$8*IF(AND(O5>=$V$8,O5<=$W$8),1,0))/$U$9*100,2) -> 98.67 | C5: sub-518 | D5: ses-1 | E5: EyesClosed | F5: post | G5: USABLE_WITH_FLAGS | H5: FLAG | I5: 0 | J5: 0 | K5: 0 | L5: 0.82 | M5: 5.19 | N5: 0.28 | O5: 187 | P5: 5.39 | R5: NO_ALPHA_BLOCKING | T5: Median spatial correlation (higher = better) | U5: 15 | V5: 0.8 | W5: 0.55
A6: =IF(G6="REJECT",COUNTIF($G$2:$G$2277,"<>REJECT")+1+COUNTIFS($G$2:$G$2277,"REJECT",$B$2:$B$2277,">"&B6),1+COUNTIFS($G$2:$G$2277,"<>REJECT",$B$2:$B$2277,">"&B6)) -> 5 | B6: =ROUND(($U$2*MAX(0,MIN(1,($W$2-I6)/($W$2-$V$2)))+$U$3*MAX(0,MIN(1,($W$3-J6)/($W$3-$V$3)))+$U$4*MAX(0,MIN(1,($W$4-K6)/($W$4-$V$4)))+$U$5*MAX(0,MIN(1,($W$5-L6)/($W$5-$V$5)))+$U$6*MAX(0,MIN(1,($W$6-M6)/($W$6-$V$6)))+$U$7*MAX(0,MIN(1,($W$7-N6)/($W$7-$V$7)))+$U$8*IF(AND(O6>=$V$8,O6<=$W$8),1,0))/$U$9*100,2) -> 98.6 | C6: sub-219 | D6: ses-1 | E6: EyesClosed | F6: post | G6: USABLE | H6: PASS | I6: 0 | J6: 0 | K6: 0 | L6: 0.79 | M6: 2.38 | N6: 0.24 | O6: 215 | P6: 9.42 | T6: 50 Hz line noise (dB) | U6: 5 | V6: 0 | W6: 30
A7: =IF(G7="REJECT",COUNTIF($G$2:$G$2277,"<>REJECT")+1+COUNTIFS($G$2:$G$2277,"REJECT",$B$2:$B$2277,">"&B7),1+COUNTIFS($G$2:$G$2277,"<>REJECT",$B$2:$B$2277,">"&B7)) -> 6 | B7: =ROUND(($U$2*MAX(0,MIN(1,($W$2-I7)/($W$2-$V$2)))+$U$3*MAX(0,MIN(1,($W$3-J7)/($W$3-$V$3)))+$U$4*MAX(0,MIN(1,($W$4-K7)/($W$4-$V$4)))+$U$5*MAX(0,MIN(1,($W$5-L7)/($W$5-$V$5)))+$U$6*MAX(0,MIN(1,($W$6-M7)/($W$6-$V$6)))+$U$7*MAX(0,MIN(1,($W$7-N7)/($W$7-$V$7)))+$U$8*IF(AND(O7>=$V$8,O7<=$W$8),1,0))/$U$9*100,2) -> 98.55 | C7: sub-016 | D7: ses-1 | E7: EyesOpen | F7: post | G7: USABLE | H7: PASS | I7: 0 | J7: 0 | K7: 0 | L7: 0.81 | M7: 8.68 | N7: 0 | O7: 187 | P7: 7.57 | T7: Frozen / flat segments (s) | U7: 5 | V7: 0 | W7: 3
A8: =IF(G8="REJECT",COUNTIF($G$2:$G$2277,"<>REJECT")+1+COUNTIFS($G$2:$G$2277,"REJECT",$B$2:$B$2277,">"&B8),1+COUNTIFS($G$2:$G$2277,"<>REJECT",$B$2:$B$2277,">"&B8)) -> 7 | B8: =ROUND(($U$2*MAX(0,MIN(1,($W$2-I8)/($W$2-$V$2)))+$U$3*MAX(0,MIN(1,($W$3-J8)/($W$3-$V$3)))+$U$4*MAX(0,MIN(1,($W$4-K8)/($W$4-$V$4)))+$U$5*MAX(0,MIN(1,($W$5-L8)/($W$5-$V$5)))+$U$6*MAX(0,MIN(1,($W$6-M8)/($W$6-$V$6)))+$U$7*MAX(0,MIN(1,($W$7-N8)/($W$7-$V$7)))+$U$8*IF(AND(O8>=$V$8,O8<=$W$8),1,0))/$U$9*100,2) -> 98.53 | C8: sub-576 | D8: ses-1 | E8: EyesOpen | F8: pre | G8: USABLE | H8: PASS | I8: 0 | J8: 0 | K8: 0 | L8: 0.8 | M8: 6.41 | N8: 0.24 | O8: 188 | P8: 4.13 | T8: Duration inside range (s): from / to | U8: 5 | V8: 120 | W8: 240
A9: =IF(G9="REJECT",COUNTIF($G$2:$G$2277,"<>REJECT")+1+COUNTIFS($G$2:$G$2277,"REJECT",$B$2:$B$2277,">"&B9),1+COUNTIFS($G$2:$G$2277,"<>REJECT",$B$2:$B$2277,">"&B9)) -> 8 | B9: =ROUND(($U$2*MAX(0,MIN(1,($W$2-I9)/($W$2-$V$2)))+$U$3*MAX(0,MIN(1,($W$3-J9)/($W$3-$V$3)))+$U$4*MAX(0,MIN(1,($W$4-K9)/($W$4-$V$4)))+$U$5*MAX(0,MIN(1,($W$5-L9)/($W$5-$V$5)))+$U$6*MAX(0,MIN(1,($W$6-M9)/($W$6-$V$6)))+$U$7*MAX(0,MIN(1,($W$7-N9)/($W$7-$V$7)))+$U$8*IF(AND(O9>=$V$8,O9<=$W$8),1,0))/$U$9*100,2) -> 98.5 | C9: sub-368 | D9: ses-2 | E9: EyesOpen | F9: pre | G9: USABLE | H9: PASS | I9: 0 | J9: 0 | K9: 0 | L9: 0.81 | M9: 7.79 | N9: 0.12 | O9: 183 | P9: 1.5 | T9: Total weight | U9: =SUM(U2:U8) -> 100
A10: =IF(G10="REJECT",COUNTIF($G$2:$G$2277,"<>REJECT")+1+COUNTIFS($G$2:$G$2277,"REJECT",$B$2:$B$2277,">"&B10),1+COUNTIFS($G$2:$G$2277,"<>REJECT",$B$2:$B$2277,">"&B10)) -> 9 | B10: =ROUND(($U$2*MAX(0,MIN(1,($W$2-I10)/($W$2-$V$2)))+$U$3*MAX(0,MIN(1,($W$3-J10)/($W$3-$V$3)))+$U$4*MAX(0,MIN(1,($W$4-K10)/($W$4-$V$4)))+$U$5*MAX(0,MIN(1,($W$5-L10)/($W$5-$V$5)))+$U$6*MAX(0,MIN(1,($W$6-M10)/($W$6-$V$6)))+$U$7*MAX(0,MIN(1,($W$7-N10)/($W$7-$V$7)))+$U$8*IF(AND(O10>=$V$8,O10<=$W$8),1,0))/$U$9*100,2) -> 98.47 | C10: sub-088 | D10: ses-1 | E10: EyesOpen | F10: post | G10: USABLE | H10: PASS | I10: 0 | J10: 0 | K10: 0 | L10: 0.8 | M10: 9.21 | N10: 0 | O10: 196 | P10: 2.64
A11: =IF(G11="REJECT",COUNTIF($G$2:$G$2277,"<>REJECT")+1+COUNTIFS($G$2:$G$2277,"REJECT",$B$2:$B$2277,">"&B11),1+COUNTIFS($G$2:$G$2277,"<>REJECT",$B$2:$B$2277,">"&B11)) -> 10 | B11: =ROUND(($U$2*MAX(0,MIN(1,($W$2-I11)/($W$2-$V$2)))+$U$3*MAX(0,MIN(1,($W$3-J11)/($W$3-$V$3)))+$U$4*MAX(0,MIN(1,($W$4-K11)/($W$4-$V$4)))+$U$5*MAX(0,MIN(1,($W$5-L11)/($W$5-$V$5)))+$U$6*MAX(0,MIN(1,($W$6-M11)/($W$6-$V$6)))+$U$7*MAX(0,MIN(1,($W$7-N11)/($W$7-$V$7)))+$U$8*IF(AND(O11>=$V$8,O11<=$W$8),1,0))/$U$9*100,2) -> 98.42 | C11: sub-266 | D11: ses-1 | E11: EyesClosed | F11: post | G11: USABLE | H11: PASS | I11: 0 | J11: 0 | K11: 0 | L11: 0.84 | M11: 5.1 | N11: 0.44 | O11: 185 | P11: 7.79 | T11: How to read this sheet
A12: =IF(G12="REJECT",COUNTIF($G$2:$G$2277,"<>REJECT")+1+COUNTIFS($G$2:$G$2277,"REJECT",$B$2:$B$2277,">"&B12),1+COUNTIFS($G$2:$G$2277,"<>REJECT",$B$2:$B$2277,">"&B12)) -> 11 | B12: =ROUND(($U$2*MAX(0,MIN(1,($W$2-I12)/($W$2-$V$2)))+$U$3*MAX(0,MIN(1,($W$3-J12)/($W$3-$V$3)))+$U$4*MAX(0,MIN(1,($W$4-K12)/($W$4-$V$4)))+$U$5*MAX(0,MIN(1,($W$5-L12)/($W$5-$V$5)))+$U$6*MAX(0,MIN(1,($W$6-M12)/($W$6-$V$6)))+$U$7*MAX(0,MIN(1,($W$7-N12)/($W$7-$V$7)))+$U$8*IF(AND(O12>=$V$8,O12<=$W$8),1,0))/$U$9*100,2) -> 98.32 | C12: sub-576 | D12: ses-1 | E12: EyesOpen | F12: post | G12: USABLE | H12: PASS | I12: 0 | J12: 0 | K12: 0 | L12: 0.85 | M12: 4.11 | N12: 0.6 | O12: 187 | P12: 7.15 | T12: - One row = one EEG recording (session / task / acq). Rows are pre-sorted best to worst, regardless of subject.
A13: =IF(G13="REJECT",COUNTIF($G$2:$G$2277,"<>REJECT")+1+COUNTIFS($G$2:$G$2277,"REJECT",$B$2:$B$2277,">"&B13),1+COUNTIFS($G$2:$G$2277,"<>REJECT",$B$2:$B$2277,">"&B13)) -> 12 | B13: =ROUND(($U$2*MAX(0,MIN(1,($W$2-I13)/($W$2-$V$2)))+$U$3*MAX(0,MIN(1,($W$3-J13)/($W$3-$V$3)))+$U$4*MAX(0,MIN(1,($W$4-K13)/($W$4-$V$4)))+$U$5*MAX(0,MIN(1,($W$5-L13)/($W$5-$V$5)))+$U$6*MAX(0,MIN(1,($W$6-M13)/($W$6-$V$6)))+$U$7*MAX(0,MIN(1,($W$7-N13)/($W$7-$V$7)))+$U$8*IF(AND(O13>=$V$8,O13<=$W$8),1,0))/$U$9*100,2) -> 98.29 | C13: sub-399 | D13: ses-1 | E13: EyesClosed | F13: post | G13: USABLE_WITH_FLAGS | H13: FLAG | I13: 0 | J13: 0 | K13: 0 | L13: 0.81 | M13: 3.87 | N13: 0.64 | O13: 184 | P13: -1.08 | R13: LOW_ALPHA_PROMINENCE | T13: - Quality score = weighted average of 7 sub-scores (0-1 each, linear between "best" and "worst" value) x 100.
A14: =IF(G14="REJECT",COUNTIF($G$2:$G$2277,"<>REJECT")+1+COUNTIFS($G$2:$G$2277,"REJECT",$B$2:$B$2277,">"&B14),1+COUNTIFS($G$2:$G$2277,"<>REJECT",$B$2:$B$2277,">"&B14)) -> 13 | B14: =ROUND(($U$2*MAX(0,MIN(1,($W$2-I14)/($W$2-$V$2)))+$U$3*MAX(0,MIN(1,($W$3-J14)/($W$3-$V$3)))+$U$4*MAX(0,MIN(1,($W$4-K14)/($W$4-$V$4)))+$U$5*MAX(0,MIN(1,($W$5-L14)/($W$5-$V$5)))+$U$6*MAX(0,MIN(1,($W$6-M14)/($W$6-$V$6)))+$U$7*MAX(0,MIN(1,($W$7-N14)/($W$7-$V$7)))+$U$8*IF(AND(O14>=$V$8,O14<=$W$8),1,0))/$U$9*100,2) -> 98.27 | C14: sub-307 | D14: ses-1 | E14: EyesClosed | F14: post | G14: USABLE_WITH_FLAGS | H14: FLAG | I14: 0 | J14: 0 | K14: 0 | L14: 0.8 | M14: 10.4 | N14: 0 | O14: 198 | P14: 13.57 | R14: WEAK_ALPHA_BLOCKING | T14: - All usable recordings (USABLE / WITH_FLAGS / NEEDS_INTERPOLATION) rank above every REJECT recording.
A15: =IF(G15="REJECT",COUNTIF($G$2:$G$2277,"<>REJECT")+1+COUNTIFS($G$2:$G$2277,"REJECT",$B$2:$B$2277,">"&B15),1+COUNTIFS($G$2:$G$2277,"<>REJECT",$B$2:$B$2277,">"&B15)) -> 14 | B15: =ROUND(($U$2*MAX(0,MIN(1,($W$2-I15)/($W$2-$V$2)))+$U$3*MAX(0,MIN(1,($W$3-J15)/($W$3-$V$3)))+$U$4*MAX(0,MIN(1,($W$4-K15)/($W$4-$V$4)))+$U$5*MAX(0,MIN(1,($W$5-L15)/($W$5-$V$5)))+$U$6*MAX(0,MIN(1,($W$6-M15)/($W$6-$V$6)))+$U$7*MAX(0,MIN(1,($W$7-N15)/($W$7-$V$7)))+$U$8*IF(AND(O15>=$V$8,O15<=$W$8),1,0))/$U$9*100,2) -> 98.26 | C15: sub-411 | D15: ses-1 | E15: EyesOpen | F15: post | G15: USABLE | H15: PASS | I15: 0 | J15: 0 | K15: 0 | L15: 0.82 | M15: 6.03 | N15: 0.44 | O15: 183 | P15: 6.88 | T15: - Score is judged on signal quality only. Alpha is NOT in the score (non-responders exist); see column P.
A16: =IF(G16="REJECT",COUNTIF($G$2:$G$2277,"<>REJECT")+1+COUNTIFS($G$2:$G$2277,"REJECT",$B$2:$B$2277,">"&B16),1+COUNTIFS($G$2:$G$2277,"<>REJECT",$B$2:$B$2277,">"&B16)) -> 15 | B16: =ROUND(($U$2*MAX(0,MIN(1,($W$2-I16)/($W$2-$V$2)))+$U$3*MAX(0,MIN(1,($W$3-J16)/($W$3-$V$3)))+$U$4*MAX(0,MIN(1,($W$4-K16)/($W$4-$V$4)))+$U$5*MAX(0,MIN(1,($W$5-L16)/($W$5-$V$5)))+$U$6*MAX(0,MIN(1,($W$6-M16)/($W$6-$V$6)))+$U$7*MAX(0,MIN(1,($W$7-N16)/($W$7-$V$7)))+$U$8*IF(AND(O16>=$V$8,O16<=$W$8),1,0))/$U$9*100,2) -> 98.24 | C16: sub-584 | D16: ses-1 | E16: EyesClosed | F16: pre | G16: USABLE_WITH_FLAGS | H16: FLAG | I16: 0 | J16: 0 | K16: 0 | L16: 0.8 | M16: 10.58 | N16: 0 | O16: 183 | P16: 0.39 | R16: LOW_ALPHA_PROMINENCE; WEAK_ALPHA_BLOCKING | T16: - Blue cells are editable inputs: the score and Rank recalculate. To re-order the rows, sort by column A.
A17: =IF(G17="REJECT",COUNTIF($G$2:$G$2277,"<>REJECT")+1+COUNTIFS($G$2:$G$2277,"REJECT",$B$2:$B$2277,">"&B17),1+COUNTIFS($G$2:$G$2277,"<>REJECT",$B$2:$B$2277,">"&B17)) -> 16 | B17: =ROUND(($U$2*MAX(0,MIN(1,($W$2-I17)/($W$2-$V$2)))+$U$3*MAX(0,MIN(1,($W$3-J17)/($W$3-$V$3)))+$U$4*MAX(0,MIN(1,($W$4-K17)/($W$4-$V$4)))+$U$5*MAX(0,MIN(1,($W$5-L17)/($W$5-$V$5)))+$U$6*MAX(0,MIN(1,($W$6-M17)/($W$6-$V$6)))+$U$7*MAX(0,MIN(1,($W$7-N17)/($W$7-$V$7)))+$U$8*IF(AND(O17>=$V$8,O17<=$W$8),1,0))/$U$9*100,2) -> 98.17 | C17: sub-439 | D17: ses-1 | E17: EyesClosed | F17: pre | G17: USABLE | H17: PASS | I17: 0 | J17: 0 | K17: 0 | L17: 0.82 | M17: 11.01 | N17: 0 | O17: 182 | P17: 9.17 | T17: - Duration row: full score if duration is between the two values, otherwise 0.
A18: =IF(G18="REJECT",COUNTIF($G$2:$G$2277,"<>REJECT")+1+COUNTIFS($G$2:$G$2277,"REJECT",$B$2:$B$2277,">"&B18),1+COUNTIFS($G$2:$G$2277,"<>REJECT",$B$2:$B$2277,">"&B18)) -> 17 | B18: =ROUND(($U$2*MAX(0,MIN(1,($W$2-I18)/($W$2-$V$2)))+$U$3*MAX(0,MIN(1,($W$3-J18)/($W$3-$V$3)))+$U$4*MAX(0,MIN(1,($W$4-K18)/($W$4-$V$4)))+$U$5*MAX(0,MIN(1,($W$5-L18)/($W$5-$V$5)))+$U$6*MAX(0,MIN(1,($W$6-M18)/($W$6-$V$6)))+$U$7*MAX(0,MIN(1,($W$7-N18)/($W$7-$V$7)))+$U$8*IF(AND(O18>=$V$8,O18<=$W$8),1,0))/$U$9*100,2) -> 98.12 | C18: sub-216 | D18: ses-1 | E18: EyesOpen | F18: pre | G18: USABLE | H18: PASS | I18: 0 | J18: 0 | K18: 0 | L18: 0.81 | M18: 11.29 | N18: 0 | O18: 194 | P18: 4.05 | T18: - Weights and cut-offs are my choice, based on the QC script thresholds (e.g. 6 bad ch = limit, 30 dB = high noise).
A19: =IF(G19="REJECT",COUNTIF($G$2:$G$2277,"<>REJECT")+1+COUNTIFS($G$2:$G$2277,"REJECT",$B$2:$B$2277,">"&B19),1+COUNTIFS($G$2:$G$2277,"<>REJECT",$B$2:$B$2277,">"&B19)) -> 18 | B19: =ROUND(($U$2*MAX(0,MIN(1,($W$2-I19)/($W$2-$V$2)))+$U$3*MAX(0,MIN(1,($W$3-J19)/($W$3-$V$3)))+$U$4*MAX(0,MIN(1,($W$4-K19)/($W$4-$V$4)))+$U$5*MAX(0,MIN(1,($W$5-L19)/($W$5-$V$5)))+$U$6*MAX(0,MIN(1,($W$6-M19)/($W$6-$V$6)))+$U$7*MAX(0,MIN(1,($W$7-N19)/($W$7-$V$7)))+$U$8*IF(AND(O19>=$V$8,O19<=$W$8),1,0))/$U$9*100,2) -> 98.11 | C19: sub-074 | D19: ses-1 | E19: EyesClosed | F19: pre | G19: USABLE | H19: PASS | I19: 0 | J19: 0 | K19: 0 | L19: 0.8 | M19: 10.15 | N19: 0.12 | O19: 183 | P19: 11.62
A20: =IF(G20="REJECT",COUNTIF($G$2:$G$2277,"<>REJECT")+1+COUNTIFS($G$2:$G$2277,"REJECT",$B$2:$B$2277,">"&B20),1+COUNTIFS($G$2:$G$2277,"<>REJECT",$B$2:$B$2277,">"&B20)) -> 19 | B20: =ROUND(($U$2*MAX(0,MIN(1,($W$2-I20)/($W$2-$V$2)))+$U$3*MAX(0,MIN(1,($W$3-J20)/($W$3-$V$3)))+$U$4*MAX(0,MIN(1,($W$4-K20)/($W$4-$V$4)))+$U$5*MAX(0,MIN(1,($W$5-L20)/($W$5-$V$5)))+$U$6*MAX(0,MIN(1,($W$6-M20)/($W$6-$V$6)))+$U$7*MAX(0,MIN(1,($W$7-N20)/($W$7-$V$7)))+$U$8*IF(AND(O20>=$V$8,O20<=$W$8),1,0))/$U$9*100,2) -> 98.1 | C20: sub-266 | D20: ses-1 | E20: EyesClosed | F20: pre | G20: USABLE | H20: PASS | I20: 0 | J20: 0 | K20: 0 | L20: 0.83 | M20: 4.19 | N20: 0.72 | O20: 185 | P20: 11.56
A21: =IF(G21="REJECT",COUNTIF($G$2:$G$2277,"<>REJECT")+1+COUNTIFS($G$2:$G$2277,"REJECT",$B$2:$B$2277,">"&B21),1+COUNTIFS($G$2:$G$2277,"<>REJECT",$B$2:$B$2277,">"&B21)) -> 20 | B21: =ROUND(($U$2*MAX(0,MIN(1,($W$2-I21)/($W$2-$V$2)))+$U$3*MAX(0,MIN(1,($W$3-J21)/($W$3-$V$3)))+$U$4*MAX(0,MIN(1,($W$4-K21)/($W$4-$V$4)))+$U$5*MAX(0,MIN(1,($W$5-L21)/($W$5-$V$5)))+$U$6*MAX(0,MIN(1,($W$6-M21)/($W$6-$V$6)))+$U$7*MAX(0,MIN(1,($W$7-N21)/($W$7-$V$7)))+$U$8*IF(AND(O21>=$V$8,O21<=$W$8),1,0))/$U$9*100,2) -> 98.06 | C21: sub-411 | D21: ses-1 | E21: EyesClosed | F21: post | G21: USABLE | H21: PASS | I21: 0 | J21: 0 | K21: 0 | L21: 0.82 | M21: 6.04 | N21: 0.56 | O21: 184 | P21: 7.92
A22: =IF(G22="REJECT",COUNTIF($G$2:$G$2277,"<>REJECT")+1+COUNTIFS($G$2:$G$2277,"REJECT",$B$2:$B$2277,">"&B22),1+COUNTIFS($G$2:$G$2277,"<>REJECT",$B$2:$B$2277,">"&B22)) -> 21 | B22: =ROUND(($U$2*MAX(0,MIN(1,($W$2-I22)/($W$2-$V$2)))+$U$3*MAX(0,MIN(1,($W$3-J22)/($W$3-$V$3)))+$U$4*MAX(0,MIN(1,($W$4-K22)/($W$4-$V$4)))+$U$5*MAX(0,MIN(1,($W$5-L22)/($W$5-$V$5)))+$U$6*MAX(0,MIN(1,($W$6-M22)/($W$6-$V$6)))+$U$7*MAX(0,MIN(1,($W$7-N22)/($W$7-$V$7)))+$U$8*IF(AND(O22>=$V$8,O22<=$W$8),1,0))/$U$9*100,2) -> 98.05 | C22: sub-298 | D22: ses-1 | E22: EyesClosed | F22: post | G22: USABLE_WITH_FLAGS | H22: FLAG | I22: 0 | J22: 0 | K22: 0 | L22: 0.79 | M22: 1.72 | N22: 0.64 | O22: 186 | P22: -0.97 | R22: LOW_ALPHA_PROMINENCE
A23: =IF(G23="REJECT",COUNTIF($G$2:$G$2277,"<>REJECT")+1+COUNTIFS($G$2:$G$2277,"REJECT",$B$2:$B$2277,">"&B23),1+COUNTIFS($G$2:$G$2277,"<>REJECT",$B$2:$B$2277,">"&B23)) -> 22 | B23: =ROUND(($U$2*MAX(0,MIN(1,($W$2-I23)/($W$2-$V$2)))+$U$3*MAX(0,MIN(1,($W$3-J23)/($W$3-$V$3)))+$U$4*MAX(0,MIN(1,($W$4-K23)/($W$4-$V$4)))+$U$5*MAX(0,MIN(1,($W$5-L23)/($W$5-$V$5)))+$U$6*MAX(0,MIN(1,($W$6-M23)/($W$6-$V$6)))+$U$7*MAX(0,MIN(1,($W$7-N23)/($W$7-$V$7)))+$U$8*IF(AND(O23>=$V$8,O23<=$W$8),1,0))/$U$9*100,2) -> 98.03 | C23: sub-074 | D23: ses-1 | E23: EyesClosed | F23: post | G23: USABLE | H23: PASS | I23: 0 | J23: 0 | K23: 0 | L23: 0.82 | M23: 4.21 | N23: 0.76 | O23: 183 | P23: 11.29
A24: =IF(G24="REJECT",COUNTIF($G$2:$G$2277,"<>REJECT")+1+COUNTIFS($G$2:$G$2277,"REJECT",$B$2:$B$2277,">"&B24),1+COUNTIFS($G$2:$G$2277,"<>REJECT",$B$2:$B$2277,">"&B24)) -> 22 | B24: =ROUND(($U$2*MAX(0,MIN(1,($W$2-I24)/($W$2-$V$2)))+$U$3*MAX(0,MIN(1,($W$3-J24)/($W$3-$V$3)))+$U$4*MAX(0,MIN(1,($W$4-K24)/($W$4-$V$4)))+$U$5*MAX(0,MIN(1,($W$5-L24)/($W$5-$V$5)))+$U$6*MAX(0,MIN(1,($W$6-M24)/($W$6-$V$6)))+$U$7*MAX(0,MIN(1,($W$7-N24)/($W$7-$V$7)))+$U$8*IF(AND(O24>=$V$8,O24<=$W$8),1,0))/$U$9*100,2) -> 98.03 | C24: sub-479 | D24: ses-1 | E24: EyesClosed | F24: post | G24: USABLE_WITH_FLAGS | H24: FLAG | I24: 0 | J24: 0 | K24: 0 | L24: 0.79 | M24: 4.61 | N24: 0.36 | O24: 183 | P24: 2.16 | R24: LOW_ALPHA_PROMINENCE; NO_ALPHA_BLOCKING
A25: =IF(G25="REJECT",COUNTIF($G$2:$G$2277,"<>REJECT")+1+COUNTIFS($G$2:$G$2277,"REJECT",$B$2:$B$2277,">"&B25),1+COUNTIFS($G$2:$G$2277,"<>REJECT",$B$2:$B$2277,">"&B25)) -> 24 | B25: =ROUND(($U$2*MAX(0,MIN(1,($W$2-I25)/($W$2-$V$2)))+$U$3*MAX(0,MIN(1,($W$3-J25)/($W$3-$V$3)))+$U$4*MAX(0,MIN(1,($W$4-K25)/($W$4-$V$4)))+$U$5*MAX(0,MIN(1,($W$5-L25)/($W$5-$V$5)))+$U$6*MAX(0,MIN(1,($W$6-M25)/($W$6-$V$6)))+$U$7*MAX(0,MIN(1,($W$7-N25)/($W$7-$V$7)))+$U$8*IF(AND(O25>=$V$8,O25<=$W$8),1,0))/$U$9*100,2) -> 98 | C25: sub-214 | D25: ses-1 | E25: EyesClosed | F25: post | G25: USABLE_WITH_FLAGS | H25: FLAG | I25: 0 | J25: 0 | K25: 0 | L25: 0.85 | M25: 9.63 | N25: 0.24 | O25: 187 | P25: -1.56 | R25: LOW_ALPHA_PROMINENCE; WEAK_ALPHA_BLOCKING
A26: =IF(G26="REJECT",COUNTIF($G$2:$G$2277,"<>REJECT")+1+COUNTIFS($G$2:$G$2277,"REJECT",$B$2:$B$2277,">"&B26),1+COUNTIFS($G$2:$G$2277,"<>REJECT",$B$2:$B$2277,">"&B26)) -> 24 | B26: =ROUND(($U$2*MAX(0,MIN(1,($W$2-I26)/($W$2-$V$2)))+$U$3*MAX(0,MIN(1,($W$3-J26)/($W$3-$V$3)))+$U$4*MAX(0,MIN(1,($W$4-K26)/($W$4-$V$4)))+$U$5*MAX(0,MIN(1,($W$5-L26)/($W$5-$V$5)))+$U$6*MAX(0,MIN(1,($W$6-M26)/($W$6-$V$6)))+$U$7*MAX(0,MIN(1,($W$7-N26)/($W$7-$V$7)))+$U$8*IF(AND(O26>=$V$8,O26<=$W$8),1,0))/$U$9*100,2) -> 98 | C26: sub-451 | D26: ses-1 | E26: EyesOpen | F26: pre | G26: USABLE | H26: PASS | I26: 0 | J26: 0 | K26: 0 | L26: 0.82 | M26: 11.99 | N26: 0 | O26: 185 | P26: 2.7
A27: =IF(G27="REJECT",COUNTIF($G$2:$G$2277,"<>REJECT")+1+COUNTIFS($G$2:$G$2277,"REJECT",$B$2:$B$2277,">"&B27),1+COUNTIFS($G$2:$G$2277,"<>REJECT",$B$2:$B$2277,">"&B27)) -> 26 | B27: =ROUND(($U$2*MAX(0,MIN(1,($W$2-I27)/($W$2-$V$2)))+$U$3*MAX(0,MIN(1,($W$3-J27)/($W$3-$V$3)))+$U$4*MAX(0,MIN(1,($W$4-K27)/($W$4-$V$4)))+$U$5*MAX(0,MIN(1,($W$5-L27)/($W$5-$V$5)))+$U$6*MAX(0,MIN(1,($W$6-M27)/($W$6-$V$6)))+$U$7*MAX(0,MIN(1,($W$7-N27)/($W$7-$V$7)))+$U$8*IF(AND(O27>=$V$8,O27<=$W$8),1,0))/$U$9*100,2) -> 97.95 | C27: sub-194 | D27: ses-1 | E27: EyesClosed | F27: pre | G27: USABLE_WITH_FLAGS | H27: FLAG | I27: 0 | J27: 0 | K27: 0 | L27: 0.81 | M27: 2.73 | N27: 0.96 | O27: 184 | P27: -1.21 | R27: LOW_ALPHA_PROMINENCE
A28: =IF(G28="REJECT",COUNTIF($G$2:$G$2277,"<>REJECT")+1+COUNTIFS($G$2:$G$2277,"REJECT",$B$2:$B$2277,">"&B28),1+COUNTIFS($G$2:$G$2277,"<>REJECT",$B$2:$B$2277,">"&B28)) -> 26 | B28: =ROUND(($U$2*MAX(0,MIN(1,($W$2-I28)/($W$2-$V$2)))+$U$3*MAX(0,MIN(1,($W$3-J28)/($W$3-$V$3)))+$U$4*MAX(0,MIN(1,($W$4-K28)/($W$4-$V$4)))+$U$5*MAX(0,MIN(1,($W$5-L28)/($W$5-$V$5)))+$U$6*MAX(0,MIN(1,($W$6-M28)/($W$6-$V$6)))+$U$7*MAX(0,MIN(1,($W$7-N28)/($W$7-$V$7)))+$U$8*IF(AND(O28>=$V$8,O28<=$W$8),1,0))/$U$9*100,2) -> 97.95 | C28: sub-258 | D28: ses-1 | E28: EyesClosed | F28: post | G28: USABLE | H28: PASS | I28: 0 | J28: 0 | K28: 0 | L28: 0.8 | M28: 6.28 | N28: 0.6 | O28: 184 | P28: 3.41
A29: =IF(G29="REJECT",COUNTIF($G$2:$G$2277,"<>REJECT")+1+COUNTIFS($G$2:$G$2277,"REJECT",$B$2:$B$2277,">"&B29),1+COUNTIFS($G$2:$G$2277,"<>REJECT",$B$2:$B$2277,">"&B29)) -> 28 | B29: =ROUND(($U$2*MAX(0,MIN(1,($W$2-I29)/($W$2-$V$2)))+$U$3*MAX(0,MIN(1,($W$3-J29)/($W$3-$V$3)))+$U$4*MAX(0,MIN(1,($W$4-K29)/($W$4-$V$4)))+$U$5*MAX(0,MIN(1,($W$5-L29)/($W$5-$V$5)))+$U$6*MAX(0,MIN(1,($W$6-M29)/($W$6-$V$6)))+$U$7*MAX(0,MIN(1,($W$7-N29)/($W$7-$V$7)))+$U$8*IF(AND(O29>=$V$8,O29<=$W$8),1,0))/$U$9*100,2) -> 97.94 | C29: sub-166 | D29: ses-1 | E29: EyesClosed | F29: post | G29: USABLE_WITH_FLAGS | H29: FLAG | I29: 0 | J29: 0 | K29: 0 | L29: 0.8 | M29: 3.18 | N29: 0.92 | O29: 184 | P29: -1.05 | R29: LOW_ALPHA_PROMINENCE
A30: =IF(G30="REJECT",COUNTIF($G$2:$G$2277,"<>REJECT")+1+COUNTIFS($G$2:$G$2277,"REJECT",$B$2:$B$2277,">"&B30),1+COUNTIFS($G$2:$G$2277,"<>REJECT",$B$2:$B$2277,">"&B30)) -> 29 | B30: =ROUND(($U$2*MAX(0,MIN(1,($W$2-I30)/($W$2-$V$2)))+$U$3*MAX(0,MIN(1,($W$3-J30)/($W$3-$V$3)))+$U$4*MAX(0,MIN(1,($W$4-K30)/($W$4-$V$4)))+$U$5*MAX(0,MIN(1,($W$5-L30)/($W$5-$V$5)))+$U$6*MAX(0,MIN(1,($W$6-M30)/($W$6-$V$6)))+$U$7*MAX(0,MIN(1,($W$7-N30)/($W$7-$V$7)))+$U$8*IF(AND(O30>=$V$8,O30<=$W$8),1,0))/$U$9*100,2) -> 97.93 | C30: sub-421 | D30: ses-1 | E30: EyesOpen | F30: post | G30: USABLE | H30: PASS | I30: 0 | J30: 0 | K30: 0 | L30: 0.83 | M30: 9.65 | N30: 0.28 | O30: 189 | P30: 9.36
A31: =IF(G31="REJECT",COUNTIF($G$2:$G$2277,"<>REJECT")+1+COUNTIFS($G$2:$G$2277,"REJECT",$B$2:$B$2277,">"&B31),1+COUNTIFS($G$2:$G$2277,"<>REJECT",$B$2:$B$2277,">"&B31)) -> 30 | B31: =ROUND(($U$2*MAX(0,MIN(1,($W$2-I31)/($W$2-$V$2)))+$U$3*MAX(0,MIN(1,($W$3-J31)/($W$3-$V$3)))+$U$4*MAX(0,MIN(1,($W$4-K31)/($W$4-$V$4)))+$U$5*MAX(0,MIN(1,($W$5-L31)/($W$5-$V$5)))+$U$6*MAX(0,MIN(1,($W$6-M31)/($W$6-$V$6)))+$U$7*MAX(0,MIN(1,($W$7-N31)/($W$7-$V$7)))+$U$8*IF(AND(O31>=$V$8,O31<=$W$8),1,0))/$U$9*100,2) -> 97.81 | C31: sub-281 | D31: ses-1 | E31: EyesOpen | F31: post | G31: USABLE | H31: PASS | I31: 0 | J31: 0 | K31: 0 | L31: 0.83 | M31: 10.33 | N31: 0.28 | O31: 182 | P31: 0.91
A32: =IF(G32="REJECT",COUNTIF($G$2:$G$2277,"<>REJECT")+1+COUNTIFS($G$2:$G$2277,"REJECT",$B$2:$B$2277,">"&B32),1+COUNTIFS($G$2:$G$2277,"<>REJECT",$B$2:$B$2277,">"&B32)) -> 31 | B32: =ROUND(($U$2*MAX(0,MIN(1,($W$2-I32)/($W$2-$V$2)))+$U$3*MAX(0,MIN(1,($W$3-J32)/($W$3-$V$3)))+$U$4*MAX(0,MIN(1,($W$4-K32)/($W$4-$V$4)))+$U$5*MAX(0,MIN(1,($W$5-L32)/($W$5-$V$5)))+$U$6*MAX(0,MIN(1,($W$6-M32)/($W$6-$V$6)))+$U$7*MAX(0,MIN(1,($W$7-N32)/($W$7-$V$7)))+$U$8*IF(AND(O32>=$V$8,O32<=$W$8),1,0))/$U$9*100,2) -> 97.79 | C32: sub-171 | D32: ses-1 | E32: EyesClosed | F32: pre | G32: USABLE | H32: PASS | I32: 0 | J32: 0 | K32: 0 | L32: 0.83 | M32: 11.64 | N32: 0.16 | O32: 183 | P32: 11.6
A33: =IF(G33="REJECT",COUNTIF($G$2:$G$2277,"<>REJECT")+1+COUNTIFS($G$2:$G$2277,"REJECT",$B$2:$B$2277,">"&B33),1+COUNTIFS($G$2:$G$2277,"<>REJECT",$B$2:$B$2277,">"&B33)) -> 32 | B33: =ROUND(($U$2*MAX(0,MIN(1,($W$2-I33)/($W$2-$V$2)))+$U$3*MAX(0,MIN(1,($W$3-J33)/($W$3-$V$3)))+$U$4*MAX(0,MIN(1,($W$4-K33)/($W$4-$V$4)))+$U$5*MAX(0,MIN(1,($W$5-L33)/($W$5-$V$5)))+$U$6*MAX(0,MIN(1,($W$6-M33)/($W$6-$V$6)))+$U$7*MAX(0,MIN(1,($W$7-N33)/($W$7-$V$7)))+$U$8*IF(AND(O33>=$V$8,O33<=$W$8),1,0))/$U$9*100,2) -> 97.77 | C33: sub-137 | D33: ses-1 | E33: EyesClosed | F33: post | G33: USABLE | H33: PASS | I33: 0 | J33: 0 | K33: 0 | L33: 0.84 | M33: 10.58 | N33: 0.28 | O33: 184 | P33: 9.6
A34: =IF(G34="REJECT",COUNTIF($G$2:$G$2277,"<>REJECT")+1+COUNTIFS($G$2:$G$2277,"REJECT",$B$2:$B$2277,">"&B34),1+COUNTIFS($G$2:$G$2277,"<>REJECT",$B$2:$B$2277,">"&B34)) -> 32 | B34: =ROUND(($U$2*MAX(0,MIN(1,($W$2-I34)/($W$2-$V$2)))+$U$3*MAX(0,MIN(1,($W$3-J34)/($W$3-$V$3)))+$U$4*MAX(0,MIN(1,($W$4-K34)/($W$4-$V$4)))+$U$5*MAX(0,MIN(1,($W$5-L34)/($W$5-$V$5)))+$U$6*MAX(0,MIN(1,($W$6-M34)/($W$6-$V$6)))+$U$7*MAX(0,MIN(1,($W$7-N34)/($W$7-$V$7)))+$U$8*IF(AND(O34>=$V$8,O34<=$W$8),1,0))/$U$9*100,2) -> 97.77 | C34: sub-365 | D34: ses-1 | E34: EyesOpen | F34: post | G34: USABLE_WITH_FLAGS | H34: FLAG | I34: 0 | J34: 0 | K34: 0 | L34: 0.79 | M34: 1.37 | N34: 0.84 | O34: 184 | P34: -1.32 | R34: WEAK_ALPHA_BLOCKING
A35: =IF(G35="REJECT",COUNTIF($G$2:$G$2277,"<>REJECT")+1+COUNTIFS($G$2:$G$2277,"REJECT",$B$2:$B$2277,">"&B35),1+COUNTIFS($G$2:$G$2277,"<>REJECT",$B$2:$B$2277,">"&B35)) -> 34 | B35: =ROUND(($U$2*MAX(0,MIN(1,($W$2-I35)/($W$2-$V$2)))+$U$3*MAX(0,MIN(1,($W$3-J35)/($W$3-$V$3)))+$U$4*MAX(0,MIN(1,($W$4-K35)/($W$4-$V$4)))+$U$5*MAX(0,MIN(1,($W$5-L35)/($W$5-$V$5)))+$U$6*MAX(0,MIN(1,($W$6-M35)/($W$6-$V$6)))+$U$7*MAX(0,MIN(1,($W$7-N35)/($W$7-$V$7)))+$U$8*IF(AND(O35>=$V$8,O35<=$W$8),1,0))/$U$9*100,2) -> 97.73 | C35: sub-062 | D35: ses-1 | E35: EyesClosed | F35: post | G35: USABLE_WITH_FLAGS | H35: FLAG | I35: 0 | J35: 0 | K35: 0 | L35: 0.8 | M35: 9.25 | N35: 0.44 | O35: 182 | P35: -0.66 | R35: LOW_ALPHA_PROMINENCE
A36: =IF(G36="REJECT",COUNTIF($G$2:$G$2277,"<>REJECT")+1+COUNTIFS($G$2:$G$2277,"REJECT",$B$2:$B$2277,">"&B36),1+COUNTIFS($G$2:$G$2277,"<>REJECT",$B$2:$B$2277,">"&B36)) -> 35 | B36: =ROUND(($U$2*MAX(0,MIN(1,($W$2-I36)/($W$2-$V$2)))+$U$3*MAX(0,MIN(1,($W$3-J36)/($W$3-$V$3)))+$U$4*MAX(0,MIN(1,($W$4-K36)/($W$4-$V$4)))+$U$5*MAX(0,MIN(1,($W$5-L36)/($W$5-$V$5)))+$U$6*MAX(0,MIN(1,($W$6-M36)/($W$6-$V$6)))+$U$7*MAX(0,MIN(1,($W$7-N36)/($W$7-$V$7)))+$U$8*IF(AND(O36>=$V$8,O36<=$W$8),1,0))/$U$9*100,2) -> 97.7 | C36: sub-216 | D36: ses-1 | E36: EyesClosed | F36: pre | G36: USABLE | H36: PASS | I36: 0 | J36: 0 | K36: 0 | L36: 0.81 | M36: 10.58 | N36: 0.32 | O36: 185 | P36: 10.34
A37: =IF(G37="REJECT",COUNTIF($G$2:$G$2277,"<>REJECT")+1+COUNTIFS($G$2:$G$2277,"REJECT",$B$2:$B$2277,">"&B37),1+COUNTIFS($G$2:$G$2277,"<>REJECT",$B$2:$B$2277,">"&B37)) -> 36 | B37: =ROUND(($U$2*MAX(0,MIN(1,($W$2-I37)/($W$2-$V$2)))+$U$3*MAX(0,MIN(1,($W$3-J37)/($W$3-$V$3)))+$U$4*MAX(0,MIN(1,($W$4-K37)/($W$4-$V$4)))+$U$5*MAX(0,MIN(1,($W$5-L37)/($W$5-$V$5)))+$U$6*MAX(0,MIN(1,($W$6-M37)/($W$6-$V$6)))+$U$7*MAX(0,MIN(1,($W$7-N37)/($W$7-$V$7)))+$U$8*IF(AND(O37>=$V$8,O37<=$W$8),1,0))/$U$9*100,2) -> 97.67 | C37: sub-453 | D37: ses-1 | E37: EyesClosed | F37: pre | G37: USABLE_WITH_FLAGS | H37: FLAG | I37: 0 | J37: 0 | K37: 0 | L37: 0.85 | M37: 4.41 | N37: 0.96 | O37: 184 | P37: -1.2 | R37: LOW_ALPHA_PROMINENCE
A38: =IF(G38="REJECT",COUNTIF($G$2:$G$2277,"<>REJECT")+1+COUNTIFS($G$2:$G$2277,"REJECT",$B$2:$B$2277,">"&B38),1+COUNTIFS($G$2:$G$2277,"<>REJECT",$B$2:$B$2277,">"&B38)) -> 37 | B38: =ROUND(($U$2*MAX(0,MIN(1,($W$2-I38)/($W$2-$V$2)))+$U$3*MAX(0,MIN(1,($W$3-J38)/($W$3-$V$3)))+$U$4*MAX(0,MIN(1,($W$4-K38)/($W$4-$V$4)))+$U$5*MAX(0,MIN(1,($W$5-L38)/($W$5-$V$5)))+$U$6*MAX(0,MIN(1,($W$6-M38)/($W$6-$V$6)))+$U$7*MAX(0,MIN(1,($W$7-N38)/($W$7-$V$7)))+$U$8*IF(AND(O38>=$V$8,O38<=$W$8),1,0))/$U$9*100,2) -> 97.65 | C38: sub-405 | D38: ses-1 | E38: EyesOpen | F38: post | G38: USABLE | H38: PASS | I38: 0 | J38: 0 | K38: 0 | L38: 0.84 | M38: 14.09 | N38: 0 | O38: 185 | P38: -0.59
A39: =IF(G39="REJECT",COUNTIF($G$2:$G$2277,"<>REJECT")+1+COUNTIFS($G$2:$G$2277,"REJECT",$B$2:$B$2277,">"&B39),1+COUNTIFS($G$2:$G$2277,"<>REJECT",$B$2:$B$2277,">"&B39)) -> 38 | B39: =ROUND(($U$2*MAX(0,MIN(1,($W$2-I39)/($W$2-$V$2)))+$U$3*MAX(0,MIN(1,($W$3-J39)/($W$3-$V$3)))+$U$4*MAX(0,MIN(1,($W$4-K39)/($W$4-$V$4)))+$U$5*MAX(0,MIN(1,($W$5-L39)/($W$5-$V$5)))+$U$6*MAX(0,MIN(1,($W$6-M39)/($W$6-$V$6)))+$U$7*MAX(0,MIN(1,($W$7-N39)/($W$7-$V$7)))+$U$8*IF(AND(O39>=$V$8,O39<=$W$8),1,0))/$U$9*100,2) -> 97.6 | C39: sub-171 | D39: ses-2 | E39: EyesClosed | F39: pre | G39: USABLE | H39: PASS | I39: 0 | J39: 0 | K39: 0 | L39: 0.81 | M39: 7.19 | N39: 0.72 | O39: 186 | P39: 4.53
A40: =IF(G40="REJECT",COUNTIF($G$2:$G$2277,"<>REJECT")+1+COUNTIFS($G$2:$G$2277,"REJECT",$B$2:$B$2277,">"&B40),1+COUNTIFS($G$2:$G$2277,"<>REJECT",$B$2:$B$2277,">"&B40)) -> 39 | B40: =ROUND(($U$2*MAX(0,MIN(1,($W$2-I40)/($W$2-$V$2)))+$U$3*MAX(0,MIN(1,($W$3-J40)/($W$3-$V$3)))+$U$4*MAX(0,MIN(1,($W$4-K40)/($W$4-$V$4)))+$U$5*MAX(0,MIN(1,($W$5-L40)/($W$5-$V$5)))+$U$6*MAX(0,MIN(1,($W$6-M40)/($W$6-$V$6)))+$U$7*MAX(0,MIN(1,($W$7-N40)/($W$7-$V$7)))+$U$8*IF(AND(O40>=$V$8,O40<=$W$8),1,0))/$U$9*100,2) -> 97.59 | C40: sub-298 | D40: ses-1 | E40: EyesClosed | F40: pre | G40: USABLE_WITH_FLAGS | H40: FLAG | I40: 0 | J40: 0 | K40: 0 | L40: 0.8 | M40: 9.26 | N40: 0.52 | O40: 194 | P40: -1.01 | R40: LOW_ALPHA_PROMINENCE; WEAK_ALPHA_BLOCKING
...

Sheet Recordings
A1: subject | B1: session | C1: task | D1: acq | E1: overall | F1: label | G1: codes | H1: verdict_header | I1: verdict_integrity | J1: verdict_amplitude | K1: verdict_spectral | L1: verdict_consistency | M1: duration_s | N1: n_bad_channels | O1: bad_channels | P1: bad_detail | Q1: n_critical_bad | R1: critical_bad_channels | S1: n_uncorrelated | T1: uncorrelated_channels | U1: interpolation_needed | V1: median_spatial_corr | W1: frozen_s | X1: typical_amp_uv | Y1: median_kurtosis | Z1: alpha_peak_hz | AA1: alpha_prom_db | AB1: alpha_ratio_EC_EO | AC1: alpha_non_responder_possible | AD1: line50_db | AE1: line100_db | AF1: line150_db | AG1: notch_suggested | AH1: trigger_events | AI1: load_error
A2: sub-001 | B2: ses-1 | C2: EyesClosed | D2: pre | E2: FLAG | F2: USABLE_WITH_FLAGS | G2: LINE_NOISE | H2: PASS | I2: PASS | J2: PASS | K2: FLAG | L2: PASS | M2: 184 | N2: 0 | Q2: 0 | S2: 0 | U2: =FALSE() -> FALSE | V2: 0.66 | W2: 0 | X2: 8.57 | Y2: 694.82 | Z2: 10 | AA2: 15.44 | AB2: 2.67 | AC2: =FALSE() -> FALSE | AD2: 29.18 | AE2: 17.78 | AF2: 26.91 | AG2: =TRUE() -> TRUE | AH2: 1
A3: sub-001 | B3: ses-1 | C3: EyesClosed | D3: post | E3: FLAG | F3: USABLE_NEEDS_INTERPOLATION | G3: LINE_NOISE; USABLE_NEEDS_INTERPOLATION | H3: PASS | I3: PASS | J3: PASS | K3: FLAG | L3: PASS | M3: 193 | N3: 1 | O3: FC1 | P3: FC1 (uncorrelated) | Q3: 0 | S3: 1 | T3: FC1 | U3: =TRUE() -> TRUE | V3: 0.66 | W3: 0.96 | X3: 9.49 | Y3: 334.03 | Z3: 10 | AA3: 14.77 | AB3: 5.34 | AC3: =FALSE() -> FALSE | AD3: 24.87 | AE3: 13.58 | AF3: 23.62 | AG3: =TRUE() -> TRUE | AH3: 1
A4: sub-001 | B4: ses-1 | C4: EyesOpen | D4: pre | E4: FAIL | F4: REJECT | G4: CRITICAL_CHANNEL_BAD; LINE_NOISE; TOO_MANY_BAD_CHANNELS | H4: PASS | I4: FAIL | J4: PASS | K4: FLAG | L4: PASS | M4: 184 | N4: 13 | O4: Fp1, Fp2, F3, Fz, F4, AF7, AF3, AF4, AF8, F5, F1, F2, F6 | P4: Fp1 (uncorrelated), Fp2 (uncorrelated), F3 (uncorrelated), Fz (uncorrelated), F4 (uncorrelated), AF7 (uncorrelated), AF3 (uncorrelated), AF4 (uncorrelated), AF8 (uncorrelated), F5 (uncorrelated), F1 (uncorrelated), F2 (uncorrelated), F6 (uncorrelated) | Q4: 1 | R4: Fz | S4: 13 | T4: Fp1, Fp2, F3, Fz, F4, AF7, AF3, AF4, AF8, F5, F1, F2, F6 | U4: =FALSE() -> FALSE | V4: 0.78 | W4: 0.64 | X4: 8.93 | Y4: 316.97 | Z4: 8 | AA4: -0.65 | AB4: 2.67 | AC4: =FALSE() -> FALSE | AD4: 23.15 | AE4: 11.65 | AF4: 21.94 | AG4: =TRUE() -> TRUE | AH4: 1
